Workbook
Name Periodes: 'Taux'!$H$6:$H$6

Sheet Global
B2: GLOBAL countries: Stock analysis
B5: Available source perimeter: 6 countries. Nordics stock excludes the separate CST account.
B8: Countries | H8: 2026Q1 | K8: 2026Q2 | N8: Evolution current / prior
B11: Austria | H11: =IF(ISNUMBER('GraphData'!B7),'GraphData'!B7,"n.d.") -> n.d. | K11: =IF(ISNUMBER('GraphData'!C7),'GraphData'!C7,"n.d.") -> 11992.29 | N11: =IF(ISNUMBER('GraphData'!D7),'GraphData'!D7,"n.d.") -> n.d.
B12: Italy | H12: =IF(ISNUMBER('GraphData'!B8),'GraphData'!B8,"n.d.") -> n.d. | K12: =IF(ISNUMBER('GraphData'!C8),'GraphData'!C8,"n.d.") -> 3127146 | N12: =IF(ISNUMBER('GraphData'!D8),'GraphData'!D8,"n.d.") -> n.d.
B13: South Africa | H13: =IF(ISNUMBER('GraphData'!B9),'GraphData'!B9,"n.d.") -> n.d. | K13: =IF(ISNUMBER('GraphData'!C9),'GraphData'!C9,"n.d.") -> 1905080.9 | N13: =IF(ISNUMBER('GraphData'!D9),'GraphData'!D9,"n.d.") -> n.d.
B14: Denmark | H14: =IF(ISNUMBER('GraphData'!B10),'GraphData'!B10,"n.d.") -> n.d. | K14: =IF(ISNUMBER('GraphData'!C10),'GraphData'!C10,"n.d.") -> 24388.74 | N14: =IF(ISNUMBER('GraphData'!D10),'GraphData'!D10,"n.d.") -> n.d.
B15: Norway | H15: =IF(ISNUMBER('GraphData'!B11),'GraphData'!B11,"n.d.") -> n.d. | K15: =IF(ISNUMBER('GraphData'!C11),'GraphData'!C11,"n.d.") -> 10807.639 | N15: =IF(ISNUMBER('GraphData'!D11),'GraphData'!D11,"n.d.") -> n.d.
B16: Sweden | H16: =IF(ISNUMBER('GraphData'!B12),'GraphData'!B12,"n.d.") -> n.d. | K16: =IF(ISNUMBER('GraphData'!C12),'GraphData'!C12,"n.d.") -> 14140.069 | N16: =IF(ISNUMBER('GraphData'!D12),'GraphData'!D12,"n.d.") -> n.d.
B17: TOTAL available perimeter | H17: =IF(COUNT(H11:H16)=6,SUM(H11:H16),"n.d.") -> n.d. | K17: =IF(COUNT(K11:K16)=6,SUM(K11:K16),"n.d.") -> 5093555.6 | N17: =IF(OR(COUNT(H17,K17)<>2,H17=0),"n.d.",K17/H17-1) -> n.d.
B24: Identified stock = stock to be processed + unreachable customers where this category applies.
B26: The lower chart isolates stock still to be processed. Vintage buckets are calculated from KPI_2.
B28: 2026Q1 has not been imported. The comparison is left unavailable.
B42: Positive Balance 2026Q2 Source: country workbooks and Taux.xlsx Internal
B46: GLOBAL countries: Monthly inflow and treatment efficiency
B49: EUR amounts. M-5 efficiency uses the oldest cohort in each reporting snapshot. Available source perimeter: 6 countries. Nordics stock excludes the separate CST account.
O52: Monthly flow in EUR | T52: Monthly average | V52: Jun-26 | X52: May-26 | Z52: Apr-26 | AB52: Mar-26 | AD52: Feb-26 | AF52: Jan-26
O55: Total available | T55: =IF(COUNT(T56,T57,T58,T59,T60,T61)=6,SUM(T56,T57,T58,T59,T60,T61),"n.d.") -> 1376029.1 | V55: =IF(COUNT('GraphData'!B23,'GraphData'!C23,'GraphData'!D23,'GraphData'!E23,'GraphData'!F23,'GraphData'!G23)=6,SUM('GraphData'!B23,'GraphData'!C23,'GraphData'!D23,'GraphData'!E23,'GraphData'!F23,'GraphData'!G23),"n.d.") -> 1248712.8 | X55: =IF(COUNT('GraphData'!B22,'GraphData'!C22,'GraphData'!D22,'GraphData'!E22,'GraphData'!F22,'GraphData'!G22)=6,SUM('GraphData'!B22,'GraphData'!C22,'GraphData'!D22,'GraphData'!E22,'GraphData'!F22,'GraphData'!G22),"n.d.") -> 1689854.7 | Z55: =IF(COUNT('GraphData'!B21,'GraphData'!C21,'GraphData'!D21,'GraphData'!E21,'GraphData'!F21,'GraphData'!G21)=6,SUM('GraphData'!B21,'GraphData'!C21,'GraphData'!D21,'GraphData'!E21,'GraphData'!F21,'GraphData'!G21),"n.d.") -> 1458762.6 | AB55: =IF(COUNT('GraphData'!B20,'GraphData'!C20,'GraphData'!D20,'GraphData'!E20,'GraphData'!F20,'GraphData'!G20)=6,SUM('GraphData'!B20,'GraphData'!C20,'GraphData'!D20,'GraphData'!E20,'GraphData'!F20,'GraphData'!G20),"n.d.") -> 1516785.7 | AD55: =IF(COUNT('GraphData'!B19,'GraphData'!C19,'GraphData'!D19,'GraphData'!E19,'GraphData'!F19,'GraphData'!G19)=6,SUM('GraphData'!B19,'GraphData'!C19,'GraphData'!D19,'GraphData'!E19,'GraphData'!F19,'GraphData'!G19),"n.d.") -> 1180210.9 | AF55: =IF(COUNT('GraphData'!B18,'GraphData'!C18,'GraphData'!D18,'GraphData'!E18,'GraphData'!F18,'GraphData'!G18)=6,SUM('GraphData'!B18,'GraphData'!C18,'GraphData'!D18,'GraphData'!E18,'GraphData'!F18,'GraphData'!G18),"n.d.") -> 1161847.9
O56: Austria | T56: =IF(OR(COUNTIFS('Consolidation'!$A$6:$A$11,"2026Q2",'Consolidation'!$B$6:$B$11,"AT")<>1,COUNTIFS('Consolidation'!$A$6:$A$11,"2026Q2",'Consolidation'!$B$6:$B$11,"AT",'Consolidation'!$W$6:$W$11,"n.d.")>0),"n.d.",SUMIFS('Consolidation'!$W$6:$W$11,'Consolidation'!$A$6:$A$11,"2026Q2",'Consolidation'!$B$6:$B$11,"AT")) -> 9124.2433 | V56: =IF(ISNUMBER('GraphData'!B23),'GraphData'!B23,"n.d.") -> 3156.52 | X56: =IF(ISNUMBER('GraphData'!B22),'GraphData'!B22,"n.d.") -> 11020.09 | Z56: =IF(ISNUMBER('GraphData'!B21),'GraphData'!B21,"n.d.") -> 4747.02 | AB56: =IF(ISNUMBER('GraphData'!B20),'GraphData'!B20,"n.d.") -> 25273.23 | AD56: =IF(ISNUMBER('GraphData'!B19),'GraphData'!B19,"n.d.") -> 6335.46 | AF56: =IF(ISNUMBER('GraphData'!B18),'GraphData'!B18,"n.d.") -> 4213.14
O57: Italy | T57: =IF(OR(COUNTIFS('Consolidation'!$A$6:$A$11,"2026Q2",'Consolidation'!$B$6:$B$11,"IT")<>1,COUNTIFS('Consolidation'!$A$6:$A$11,"2026Q2",'Consolidation'!$B$6:$B$11,"IT",'Consolidation'!$W$6:$W$11,"n.d.")>0),"n.d.",SUMIFS('Consolidation'!$W$6:$W$11,'Consolidation'!$A$6:$A$11,"2026Q2",'Consolidation'!$B$6:$B$11,"IT")) -> 1113086.7 | V57: =IF(ISNUMBER('GraphData'!C23),'GraphData'!C23,"n.d.") -> 977488.48 | X57: =IF(ISNUMBER('GraphData'!C22),'GraphData'!C22,"n.d.") -> 1425617.1 | Z57: =IF(ISNUMBER('GraphData'!C21),'GraphData'!C21,"n.d.") -> 1199203.8 | AB57: =IF(ISNUMBER('GraphData'!C20),'GraphData'!C20,"n.d.") -> 1177760.6 | AD57: =IF(ISNUMBER('GraphData'!C19),'GraphData'!C19,"n.d.") -> 951551.94 | AF57: =IF(ISNUMBER('GraphData'!C18),'GraphData'!C18,"n.d.") -> 946898.07
O58: South Africa | T58: =IF(OR(COUNTIFS('Consolidation'!$A$6:$A$11,"2026Q2",'Consolidation'!$B$6:$B$11,"ZA")<>1,COUNTIFS('Consolidation'!$A$6:$A$11,"2026Q2",'Consolidation'!$B$6:$B$11,"ZA",'Consolidation'!$W$6:$W$11,"n.d.")>0),"n.d.",SUMIFS('Consolidation'!$W$6:$W$11,'Consolidation'!$A$6:$A$11,"2026Q2",'Consolidation'!$B$6:$B$11,"ZA")) -> 195974.11 | V58: =IF(ISNUMBER('GraphData'!D23),'GraphData'!D23,"n.d.") -> 225610.21 | X58: =IF(ISNUMBER('GraphData'!D22),'GraphData'!D22,"n.d.") -> 206318.83 | Z58: =IF(ISNUMBER('GraphData'!D21),'GraphData'!D21,"n.d.") -> 200004.48 | AB58: =IF(ISNUMBER('GraphData'!D20),'GraphData'!D20,"n.d.") -> 211900.11 | AD58: =IF(ISNUMBER('GraphData'!D19),'GraphData'!D19,"n.d.") -> 171151.72 | AF58: =IF(ISNUMBER('GraphData'!D18),'GraphData'!D18,"n.d.") -> 160859.29
O59: Denmark | T59: =IF(OR(COUNTIFS('Consolidation'!$A$6:$A$11,"2026Q2",'Consolidation'!$B$6:$B$11,"DK")<>1,COUNTIFS('Consolidation'!$A$6:$A$11,"2026Q2",'Consolidation'!$B$6:$B$11,"DK",'Consolidation'!$W$6:$W$11,"n.d.")>0),"n.d.",SUMIFS('Consolidation'!$W$6:$W$11,'Consolidation'!$A$6:$A$11,"2026Q2",'Consolidation'!$B$6:$B$11,"DK")) -> 19196.445 | V59: =IF(ISNUMBER('GraphData'!E23),'GraphData'!E23,"n.d.") -> 11699.288 | X59: =IF(ISNUMBER('GraphData'!E22),'GraphData'!E22,"n.d.") -> 21741.322 | Z59: =IF(ISNUMBER('GraphData'!E21),'GraphData'!E21,"n.d.") -> 15036.561 | AB59: =IF(ISNUMBER('GraphData'!E20),'GraphData'!E20,"n.d.") -> 14889.542 | AD59: =IF(ISNUMBER('GraphData'!E19),'GraphData'!E19,"n.d.") -> 34334.79 | AF59: =IF(ISNUMBER('GraphData'!E18),'GraphData'!E18,"n.d.") -> 17477.168
O60: Norway | T60: =IF(OR(COUNTIFS('Consolidation'!$A$6:$A$11,"2026Q2",'Consolidation'!$B$6:$B$11,"NO")<>1,COUNTIFS('Consolidation'!$A$6:$A$11,"2026Q2",'Consolidation'!$B$6:$B$11,"NO",'Consolidation'!$W$6:$W$11,"n.d.")>0),"n.d.",SUMIFS('Consolidation'!$W$6:$W$11,'Consolidation'!$A$6:$A$11,"2026Q2",'Consolidation'!$B$6:$B$11,"NO")) -> 10244.301 | V60: =IF(ISNUMBER('GraphData'!F23),'GraphData'!F23,"n.d.") -> 5700.0426 | X60: =IF(ISNUMBER('GraphData'!F22),'GraphData'!F22,"n.d.") -> 12779.255 | Z60: =IF(ISNUMBER('GraphData'!F21),'GraphData'!F21,"n.d.") -> 5086.4277 | AB60: =IF(ISNUMBER('GraphData'!F20),'GraphData'!F20,"n.d.") -> 21895.591 | AD60: =IF(ISNUMBER('GraphData'!F19),'GraphData'!F19,"n.d.") -> 6024.428 | AF60: =IF(ISNUMBER('GraphData'!F18),'GraphData'!F18,"n.d.") -> 9980.0635
O61: Sweden | T61: =IF(OR(COUNTIFS('Consolidation'!$A$6:$A$11,"2026Q2",'Consolidation'!$B$6:$B$11,"SE")<>1,COUNTIFS('Consolidation'!$A$6:$A$11,"2026Q2",'Consolidation'!$B$6:$B$11,"SE",'Consolidation'!$W$6:$W$11,"n.d.")>0),"n.d.",SUMIFS('Consolidation'!$W$6:$W$11,'Consolidation'!$A$6:$A$11,"2026Q2",'Consolidation'!$B$6:$B$11,"SE")) -> 28403.328 | V61: =IF(ISNUMBER('GraphData'!G23),'GraphData'!G23,"n.d.") -> 25058.217 | X61: =IF(ISNUMBER('GraphData'!G22),'GraphData'!G22,"n.d.") -> 12378.132 | Z61: =IF(ISNUMBER('GraphData'!G21),'GraphData'!G21,"n.d.") -> 34684.352 | AB61: =IF(ISNUMBER('GraphData'!G20),'GraphData'!G20,"n.d.") -> 65066.573 | AD61: =IF(ISNUMBER('GraphData'!G19),'GraphData'!G19,"n.d.") -> 10812.555 | AF61: =IF(ISNUMBER('GraphData'!G18),'GraphData'!G18,"n.d.") -> 22420.142
O65: Efficiency in amount | X65: Efficiency in number
O66: Country | S66: 2026Q1 | U66: 2026Q2 | X66: Country | AB66: 2026Q1 | AD66: 2026Q2
O68: Austria | S68: n.d. | U68: ='GraphData'!E29 -> 0.90087203 | X68: Austria | AB68: n.d. | AD68: ='GraphData'!C29 -> 0.77272727
O69: Italy | S69: n.d. | U69: ='GraphData'!E30 -> 0.98437849 | X69: Italy | AB69: n.d. | AD69: ='GraphData'!C30 -> 0.9484959
O70: South Africa | S70: n.d. | U70: ='GraphData'!E31 -> 0.64934305 | X70: South Africa | AB70: n.d. | AD70: ='GraphData'!C31 -> 0.85499812
O71: Denmark | S71: n.d. | U71: ='GraphData'!E32 -> 1 | X71: Denmark | AB71: n.d. | AD71: ='GraphData'!C32 -> 1
O72: Norway | S72: n.d. | U72: ='GraphData'!E33 -> 0.94101649 | X72: Norway | AB72: n.d. | AD72: ='GraphData'!C33 -> 0.9924812
O73: Sweden | S73: n.d. | U73: ='GraphData'!E34 -> 1 | X73: Sweden | AB73: n.d. | AD73: ='GraphData'!C34 -> 1
O75: Previous-quarter series are omitted until that snapshot is imported.
B86: Positive Balance 2026Q2 Source: country workbooks and Taux.xlsx Internal

Sheet CORE Stock
B2: CORE countries: Stock analysis
B5: Available source perimeter: 3 countries.
B8: Countries | H8: 2026Q1 | K8: 2026Q2 | N8: Evolution current / prior
B11: Austria | H11: =IF(ISNUMBER('GraphData'!B40),'GraphData'!B40,"n.d.") -> n.d. | K11: =IF(ISNUMBER('GraphData'!C40),'GraphData'!C40,"n.d.") -> 11992.29 | N11: =IF(ISNUMBER('GraphData'!D40),'GraphData'!D40,"n.d.") -> n.d.
B12: Italy | H12: =IF(ISNUMBER('GraphData'!B41),'GraphData'!B41,"n.d.") -> n.d. | K12: =IF(ISNUMBER('GraphData'!C41),'GraphData'!C41,"n.d.") -> 3127146 | N12: =IF(ISNUMBER('GraphData'!D41),'GraphData'!D41,"n.d.") -> n.d.
B13: South Africa | H13: =IF(ISNUMBER('GraphData'!B42),'GraphData'!B42,"n.d.") -> n.d. | K13: =IF(ISNUMBER('GraphData'!C42),'GraphData'!C42,"n.d.") -> 1905080.9 | N13: =IF(ISNUMBER('GraphData'!D42),'GraphData'!D42,"n.d.") -> n.d.
B14: TOTAL available perimeter | H14: =IF(COUNT(H11:H13)=3,SUM(H11:H13),"n.d.") -> n.d. | K14: =IF(COUNT(K11:K13)=3,SUM(K11:K13),"n.d.") -> 5044219.2 | N14: =IF(OR(COUNT(H14,K14)<>2,H14=0),"n.d.",K14/H14-1) -> n.d.
B24: Identified stock = stock to be processed + unreachable customers where this category applies.
B26: The lower chart isolates stock still to be processed. Vintage buckets are calculated from KPI_2.
B28: 2026Q1 has not been imported. The comparison is left unavailable.
B42: Positive Balance 2026Q2 Source: country workbooks and Taux.xlsx Internal

Sheet CORE Flows
B2: CORE countries: Monthly inflow and treatment efficiency
B5: EUR amounts. M-5 efficiency uses the oldest cohort in each reporting snapshot. Available source perimeter: 3 countries.
O8: Monthly flow in EUR | T8: Monthly average | V8: Jun-26 | X8: May-26 | Z8: Apr-26 | AB8: Mar-26 | AD8: Feb-26 | AF8: Jan-26
O11: Total available | T11: =IF(COUNT(T12,T13,T14)=3,SUM(T12,T13,T14),"n.d.") -> 1318185 | V11: =IF(COUNT('GraphData'!B53,'GraphData'!C53,'GraphData'!D53)=3,SUM('GraphData'!B53,'GraphData'!C53,'GraphData'!D53),"n.d.") -> 1206255.2 | X11: =IF(COUNT('GraphData'!B52,'GraphData'!C52,'GraphData'!D52)=3,SUM('GraphData'!B52,'GraphData'!C52,'GraphData'!D52),"n.d.") -> 1642956 | Z11: =IF(COUNT('GraphData'!B51,'GraphData'!C51,'GraphData'!D51)=3,SUM('GraphData'!B51,'GraphData'!C51,'GraphData'!D51),"n.d.") -> 1403955.3 | AB11: =IF(COUNT('GraphData'!B50,'GraphData'!C50,'GraphData'!D50)=3,SUM('GraphData'!B50,'GraphData'!C50,'GraphData'!D50),"n.d.") -> 1414934 | AD11: =IF(COUNT('GraphData'!B49,'GraphData'!C49,'GraphData'!D49)=3,SUM('GraphData'!B49,'GraphData'!C49,'GraphData'!D49),"n.d.") -> 1129039.1 | AF11: =IF(COUNT('GraphData'!B48,'GraphData'!C48,'GraphData'!D48)=3,SUM('GraphData'!B48,'GraphData'!C48,'GraphData'!D48),"n.d.") -> 1111970.5
O12: Austria | T12: =IF(OR(COUNTIFS('Consolidation'!$A$6:$A$11,"2026Q2",'Consolidation'!$B$6:$B$11,"AT")<>1,COUNTIFS('Consolidation'!$A$6:$A$11,"2026Q2",'Consolidation'!$B$6:$B$11,"AT",'Consolidation'!$W$6:$W$11,"n.d.")>0),"n.d.",SUMIFS('Consolidation'!$W$6:$W$11,'Consolidation'!$A$6:$A$11,"2026Q2",'Consolidation'!$B$6:$B$11,"AT")) -> 9124.2433 | V12: =IF(ISNUMBER('GraphData'!B53),'GraphData'!B53,"n.d.") -> 3156.52 | X12: =IF(ISNUMBER('GraphData'!B52),'GraphData'!B52,"n.d.") -> 11020.09 | Z12: =IF(ISNUMBER('GraphData'!B51),'GraphData'!B51,"n.d.") -> 4747.02 | AB12: =IF(ISNUMBER('GraphData'!B50),'GraphData'!B50,"n.d.") -> 25273.23 | AD12: =IF(ISNUMBER('GraphData'!B49),'GraphData'!B49,"n.d.") -> 6335.46 | AF12: =IF(ISNUMBER('GraphData'!B48),'GraphData'!B48,"n.d.") -> 4213.14
O13: Italy | T13: =IF(OR(COUNTIFS('Consolidation'!$A$6:$A$11,"2026Q2",'Consolidation'!$B$6:$B$11,"IT")<>1,COUNTIFS('Consolidation'!$A$6:$A$11,"2026Q2",'Consolidation'!$B$6:$B$11,"IT",'Consolidation'!$W$6:$W$11,"n.d.")>0),"n.d.",SUMIFS('Consolidation'!$W$6:$W$11,'Consolidation'!$A$6:$A$11,"2026Q2",'Consolidation'!$B$6:$B$11,"IT")) -> 1113086.7 | V13: =IF(ISNUMBER('GraphData'!C53),'GraphData'!C53,"n.d.") -> 977488.48 | X13: =IF(ISNUMBER('GraphData'!C52),'GraphData'!C52,"n.d.") -> 1425617.1 | Z13: =IF(ISNUMBER('GraphData'!C51),'GraphData'!C51,"n.d.") -> 1199203.8 | AB13: =IF(ISNUMBER('GraphData'!C50),'GraphData'!C50,"n.d.") -> 1177760.6 | AD13: =IF(ISNUMBER('GraphData'!C49),'GraphData'!C49,"n.d.") -> 951551.94 | AF13: =IF(ISNUMBER('GraphData'!C48),'GraphData'!C48,"n.d.") -> 946898.07
O14: South Africa | T14: =IF(OR(COUNTIFS('Consolidation'!$A$6:$A$11,"2026Q2",'Consolidation'!$B$6:$B$11,"ZA")<>1,COUNTIFS('Consolidation'!$A$6:$A$11,"2026Q2",'Consolidation'!$B$6:$B$11,"ZA",'Consolidation'!$W$6:$W$11,"n.d.")>0),"n.d.",SUMIFS('Consolidation'!$W$6:$W$11,'Consolidation'!$A$6:$A$11,"2026Q2",'Consolidation'!$B$6:$B$11,"ZA")) -> 195974.11 | V14: =IF(ISNUMBER('GraphData'!D53),'GraphData'!D53,"n.d.") -> 225610.21 | X14: =IF(ISNUMBER('GraphData'!D52),'GraphData'!D52,"n.d.") -> 206318.83 | Z14: =IF(ISNUMBER('GraphData'!D51),'GraphData'!D51,"n.d.") -> 200004.48 | AB14: =IF(ISNUMBER('GraphData'!D50),'GraphData'!D50,"n.d.") -> 211900.11 | AD14: =IF(ISNUMBER('GraphData'!D49),'GraphData'!D49,"n.d.") -> 171151.72 | AF14: =IF(ISNUMBER('GraphData'!D48),'GraphData'!D48,"n.d.") -> 160859.29
O21: Efficiency in amount | X21: Efficiency in number
O22: Country | S22: 2026Q1 | U22: 2026Q2 | X22: Country | AB22: 2026Q1 | AD22: 2026Q2
O24: Austria | S24: n.d. | U24: ='GraphData'!E59 -> 0.90087203 | X24: Austria | AB24: n.d. | AD24: ='GraphData'!C59 -> 0.77272727
O25: Italy | S25: n.d. | U25: ='GraphData'!E60 -> 0.98437849 | X25: Italy | AB25: n.d. | AD25: ='GraphData'!C60 -> 0.9484959
O26: South Africa | S26: n.d. | U26: ='GraphData'!E61 -> 0.64934305 | X26: South Africa | AB26: n.d. | AD26: ='GraphData'!C61 -> 0.85499812
O28: Previous-quarter series are omitted until that snapshot is imported.
B42: Positive Balance 2026Q2 Source: country workbooks and Taux.xlsx Internal

Sheet NON CORE Stock
B2: NON CORE countries: Stock analysis
B5: Available source perimeter: 3 countries. Nordics stock excludes the separate CST account.
B8: Countries | H8: 2026Q1 | K8: 2026Q2 | N8: Evolution current / prior | R8: Stock in EUR | W8: Total | Z8: <2025 | AB8: 2025 | AD8: 2026
B11: Denmark | H11: =IF(ISNUMBER('GraphData'!B67),'GraphData'!B67,"n.d.") -> n.d. | K11: =IF(ISNUMBER('GraphData'!C67),'GraphData'!C67,"n.d.") -> 24388.74 | N11: =IF(ISNUMBER('GraphData'!D67),'GraphData'!D67,"n.d.") -> n.d. | R11: Denmark | W11: =IF(ISNUMBER('GraphData'!C67),'GraphData'!C67,"n.d.") -> 24388.74 | Z11: =IF(ISNUMBER('GraphData'!F67),'GraphData'!F67,"n.d.") -> 0 | AB11: =IF(ISNUMBER('GraphData'!G67),'GraphData'!G67,"n.d.") -> 3.1149283e-11 | AD11: =IF(ISNUMBER('GraphData'!H67),'GraphData'!H67,"n.d.") -> 24388.74
B12: Norway | H12: =IF(ISNUMBER('GraphData'!B68),'GraphData'!B68,"n.d.") -> n.d. | K12: =IF(ISNUMBER('GraphData'!C68),'GraphData'!C68,"n.d.") -> 10807.639 | N12: =IF(ISNUMBER('GraphData'!D68),'GraphData'!D68,"n.d.") -> n.d. | R12: Norway | W12: =IF(ISNUMBER('GraphData'!C68),'GraphData'!C68,"n.d.") -> 10807.639 | Z12: =IF(ISNUMBER('GraphData'!F68),'GraphData'!F68,"n.d.") -> 0 | AB12: =IF(ISNUMBER('GraphData'!G68),'GraphData'!G68,"n.d.") -> 4.1167924e-11 | AD12: =IF(ISNUMBER('GraphData'!H68),'GraphData'!H68,"n.d.") -> 10807.639
B13: Sweden | H13: =IF(ISNUMBER('GraphData'!B69),'GraphData'!B69,"n.d.") -> n.d. | K13: =IF(ISNUMBER('GraphData'!C69),'GraphData'!C69,"n.d.") -> 14140.069 | N13: =IF(ISNUMBER('GraphData'!D69),'GraphData'!D69,"n.d.") -> n.d. | R13: Sweden | W13: =IF(ISNUMBER('GraphData'!C69),'GraphData'!C69,"n.d.") -> 14140.069 | Z13: =IF(ISNUMBER('GraphData'!F69),'GraphData'!F69,"n.d.") -> 0 | AB13: =IF(ISNUMBER('GraphData'!G69),'GraphData'!G69,"n.d.") -> 0 | AD13: =IF(ISNUMBER('GraphData'!H69),'GraphData'!H69,"n.d.") -> 14140.069
B14: TOTAL available perimeter | H14: =IF(COUNT(H11:H13)=3,SUM(H11:H13),"n.d.") -> n.d. | K14: =IF(COUNT(K11:K13)=3,SUM(K11:K13),"n.d.") -> 49336.448 | N14: =IF(OR(COUNT(H14,K14)<>2,H14=0),"n.d.",K14/H14-1) -> n.d. | R14: TOTAL available | W14: =IF(COUNT(W11:W13)=3,SUM(W11:W13),"n.d.") -> 49336.448 | Z14: =IF(COUNT(Z11:Z13)=3,SUM(Z11:Z13),"n.d.") -> 0 | AB14: =IF(COUNT(AB11:AB13)=3,SUM(AB11:AB13),"n.d.") -> 7.2317207e-11 | AD14: =IF(COUNT(AD11:AD13)=3,SUM(AD11:AD13),"n.d.") -> 49336.448
R21: Waiting accounts for Nordics (CST)
R23: Country | W23: 2026Q1 EUR | AA23: 2026Q2 EUR | AE23: Change
B24: Identified stock = stock to be processed + unreachable customers where this category applies.
B26: The vintage table excludes the separate CST accounts. | R26: Denmark | W26: n.d. | AA26: n.d. | AE26: n.d.
R27: Norway | W27: n.d. | AA27: n.d. | AE27: n.d.
B28: 2026Q1 has not been imported. The comparison is left unavailable. | R28: Sweden | W28: n.d. | AA28: n.d. | AE28: n.d.
R31: CST balances are received separately and are not present in the source workbooks. Romania and Brazil are not included in this report.
B42: Positive Balance 2026Q2 Source: country workbooks and Taux.xlsx Internal

Sheet AT Austria
B2: Austria | R2: STOCK OF POSITIVE BALANCES to be processed (KPI_3) | X2: 46203
X3: Number of contracts | Z3: Total amount EUR | AC3: % in number | AE3: % in amount
B5: Reporting at 30 June 2026. Six monthly cohorts.
R7: By step of amount | U7: 0 - 1 € | X7: =IF(OR(SUMPRODUCT(--('Repartition stock'!$A$6:$A$94="2026Q2"),--('Repartition stock'!$B$6:$B$94="AT"),--('Repartition stock'!$E$6:$E$94="Tranche"),--('Repartition stock'!$F$6:$F$94="0 - 1 €"))=0,SUMPRODUCT(--('Repartition stock'!$A$6:$A$94="2026Q2"),--('Repartition stock'!$B$6:$B$94="AT"),--('Repartition stock'!$E$6:$E$94="Tranche"),--('Repartition stock'!$F$6:$F$94="0 - 1 €"),--('Repartition stock'!$G$6:$G$94="n.d."))>0),"n.d.",SUMPRODUCT(--('Repartition stock'!$A$6:$A$94="2026Q2"),--('Repartition stock'!$B$6:$B$94="AT"),--('Repartition stock'!$E$6:$E$94="Tranche"),--('Repartition stock'!$F$6:$F$94="0 - 1 €"),'Repartition stock'!$G$6:$G$94)) -> 5 | Z7: =IF(OR(SUMPRODUCT(--('Repartition stock'!$A$6:$A$94="2026Q2"),--('Repartition stock'!$B$6:$B$94="AT"),--('Repartition stock'!$E$6:$E$94="Tranche"),--('Repartition stock'!$F$6:$F$94="0 - 1 €"))=0,SUMPRODUCT(--('Repartition stock'!$A$6:$A$94="2026Q2"),--('Repartition stock'!$B$6:$B$94="AT"),--('Repartition stock'!$E$6:$E$94="Tranche"),--('Repartition stock'!$F$6:$F$94="0 - 1 €"),--('Repartition stock'!$J$6:$J$94="n.d."))>0),"n.d.",SUMPRODUCT(--('Repartition stock'!$A$6:$A$94="2026Q2"),--('Repartition stock'!$B$6:$B$94="AT"),--('Repartition stock'!$E$6:$E$94="Tranche"),--('Repartition stock'!$F$6:$F$94="0 - 1 €"),'Repartition stock'!$J$6:$J$94)) -> 1.21 | AC7: =IF(OR(COUNT(X7,X12)<>2,X12=0),"n.d.",X7/X12) -> 0.067567568 | AE7: =IF(OR(COUNT(Z7,Z12)<>2,Z12=0),"n.d.",Z7/Z12) -> 0.00010089816
U8: 1 - 10 € | X8: =IF(OR(SUMPRODUCT(--('Repartition stock'!$A$6:$A$94="2026Q2"),--('Repartition stock'!$B$6:$B$94="AT"),--('Repartition stock'!$E$6:$E$94="Tranche"),--('Repartition stock'!$F$6:$F$94="1 - 10 €"))=0,SUMPRODUCT(--('Repartition stock'!$A$6:$A$94="2026Q2"),--('Repartition stock'!$B$6:$B$94="AT"),--('Repartition stock'!$E$6:$E$94="Tranche"),--('Repartition stock'!$F$6:$F$94="1 - 10 €"),--('Repartition stock'!$G$6:$G$94="n.d."))>0),"n.d.",SUMPRODUCT(--('Repartition stock'!$A$6:$A$94="2026Q2"),--('Repartition stock'!$B$6:$B$94="AT"),--('Repartition stock'!$E$6:$E$94="Tranche"),--('Repartition stock'!$F$6:$F$94="1 - 10 €"),'Repartition stock'!$G$6:$G$94)) -> 19 | Z8: =IF(OR(SUMPRODUCT(--('Repartition stock'!$A$6:$A$94="2026Q2"),--('Repartition stock'!$B$6:$B$94="AT"),--('Repartition stock'!$E$6:$E$94="Tranche"),--('Repartition stock'!$F$6:$F$94="1 - 10 €"))=0,SUMPRODUCT(--('Repartition stock'!$A$6:$A$94="2026Q2"),--('Repartition stock'!$B$6:$B$94="AT"),--('Repartition stock'!$E$6:$E$94="Tranche"),--('Repartition stock'!$F$6:$F$94="1 - 10 €"),--('Repartition stock'!$J$6:$J$94="n.d."))>0),"n.d.",SUMPRODUCT(--('Repartition stock'!$A$6:$A$94="2026Q2"),--('Repartition stock'!$B$6:$B$94="AT"),--('Repartition stock'!$E$6:$E$94="Tranche"),--('Repartition stock'!$F$6:$F$94="1 - 10 €"),'Repartition stock'!$J$6:$J$94)) -> 83.42 | AC8: =IF(OR(COUNT(X8,X12)<>2,X12=0),"n.d.",X8/X12) -> 0.25675676 | AE8: =IF(OR(COUNT(Z8,Z12)<>2,Z12=0),"n.d.",Z8/Z12) -> 0.006956136
U9: 10 - 100 € | X9: =IF(OR(SUMPRODUCT(--('Repartition stock'!$A$6:$A$94="2026Q2"),--('Repartition stock'!$B$6:$B$94="AT"),--('Repartition stock'!$E$6:$E$94="Tranche"),--('Repartition stock'!$F$6:$F$94="10 - 100 €"))=0,SUMPRODUCT(--('Repartition stock'!$A$6:$A$94="2026Q2"),--('Repartition stock'!$B$6:$B$94="AT"),--('Repartition stock'!$E$6:$E$94="Tranche"),--('Repartition stock'!$F$6:$F$94="10 - 100 €"),--('Repartition stock'!$G$6:$G$94="n.d."))>0),"n.d.",SUMPRODUCT(--('Repartition stock'!$A$6:$A$94="2026Q2"),--('Repartition stock'!$B$6:$B$94="AT"),--('Repartition stock'!$E$6:$E$94="Tranche"),--('Repartition stock'!$F$6:$F$94="10 - 100 €"),'Repartition stock'!$G$6:$G$94)) -> 32 | Z9: =IF(OR(SUMPRODUCT(--('Repartition stock'!$A$6:$A$94="2026Q2"),--('Repartition stock'!$B$6:$B$94="AT"),--('Repartition stock'!$E$6:$E$94="Tranche"),--('Repartition stock'!$F$6:$F$94="10 - 100 €"))=0,SUMPRODUCT(--('Repartition stock'!$A$6:$A$94="2026Q2"),--('Repartition stock'!$B$6:$B$94="AT"),--('Repartition stock'!$E$6:$E$94="Tranche"),--('Repartition stock'!$F$6:$F$94="10 - 100 €"),--('Repartition stock'!$J$6:$J$94="n.d."))>0),"n.d.",SUMPRODUCT(--('Repartition stock'!$A$6:$A$94="2026Q2"),--('Repartition stock'!$B$6:$B$94="AT"),--('Repartition stock'!$E$6:$E$94="Tranche"),--('Repartition stock'!$F$6:$F$94="10 - 100 €"),'Repartition stock'!$J$6:$J$94)) -> 1265.6 | AC9: =IF(OR(COUNT(X9,X12)<>2,X12=0),"n.d.",X9/X12) -> 0.43243243 | AE9: =IF(OR(COUNT(Z9,Z12)<>2,Z12=0),"n.d.",Z9/Z12) -> 0.10553447
U10: 100 - 1 000 € | X10: =IF(OR(SUMPRODUCT(--('Repartition stock'!$A$6:$A$94="2026Q2"),--('Repartition stock'!$B$6:$B$94="AT"),--('Repartition stock'!$E$6:$E$94="Tranche"),--('Repartition stock'!$F$6:$F$94="100 - 1 000 €"))=0,SUMPRODUCT(--('Repartition stock'!$A$6:$A$94="2026Q2"),--('Repartition stock'!$B$6:$B$94="AT"),--('Repartition stock'!$E$6:$E$94="Tranche"),--('Repartition stock'!$F$6:$F$94="100 - 1 000 €"),--('Repartition stock'!$G$6:$G$94="n.d."))>0),"n.d.",SUMPRODUCT(--('Repartition stock'!$A$6:$A$94="2026Q2"),--('Repartition stock'!$B$6:$B$94="AT"),--('Repartition stock'!$E$6:$E$94="Tranche"),--('Repartition stock'!$F$6:$F$94="100 - 1 000 €"),'Repartition stock'!$G$6:$G$94)) -> 14 | Z10: =IF(OR(SUMPRODUCT(--('Repartition stock'!$A$6:$A$94="2026Q2"),--('Repartition stock'!$B$6:$B$94="AT"),--('Repartition stock'!$E$6:$E$94="Tranche"),--('Repartition stock'!$F$6:$F$94="100 - 1 000 €"))=0,SUMPRODUCT(--('Repartition stock'!$A$6:$A$94="2026Q2"),--('Repartition stock'!$B$6:$B$94="AT"),--('Repartition stock'!$E$6:$E$94="Tranche"),--('Repartition stock'!$F$6:$F$94="100 - 1 000 €"),--('Repartition stock'!$J$6:$J$94="n.d."))>0),"n.d.",SUMPRODUCT(--('Repartition stock'!$A$6:$A$94="2026Q2"),--('Repartition stock'!$B$6:$B$94="AT"),--('Repartition stock'!$E$6:$E$94="Tranche"),--('Repartition stock'!$F$6:$F$94="100 - 1 000 €"),'Repartition stock'!$J$6:$J$94)) -> 3254 | AC10: =IF(OR(COUNT(X10,X12)<>2,X12=0),"n.d.",X10/X12) -> 0.18918919 | AE10: =IF(OR(COUNT(Z10,Z12)<>2,Z12=0),"n.d.",Z10/Z12) -> 0.271341
U11: > 1 000 € | X11: =IF(OR(SUMPRODUCT(--('Repartition stock'!$A$6:$A$94="2026Q2"),--('Repartition stock'!$B$6:$B$94="AT"),--('Repartition stock'!$E$6:$E$94="Tranche"),--('Repartition stock'!$F$6:$F$94="> 1 000 €"))=0,SUMPRODUCT(--('Repartition stock'!$A$6:$A$94="2026Q2"),--('Repartition stock'!$B$6:$B$94="AT"),--('Repartition stock'!$E$6:$E$94="Tranche"),--('Repartition stock'!$F$6:$F$94="> 1 000 €"),--('Repartition stock'!$G$6:$G$94="n.d."))>0),"n.d.",SUMPRODUCT(--('Repartition stock'!$A$6:$A$94="2026Q2"),--('Repartition stock'!$B$6:$B$94="AT"),--('Repartition stock'!$E$6:$E$94="Tranche"),--('Repartition stock'!$F$6:$F$94="> 1 000 €"),'Repartition stock'!$G$6:$G$94)) -> 4 | Z11: =IF(OR(SUMPRODUCT(--('Repartition stock'!$A$6:$A$94="2026Q2"),--('Repartition stock'!$B$6:$B$94="AT"),--('Repartition stock'!$E$6:$E$94="Tranche"),--('Repartition stock'!$F$6:$F$94="> 1 000 €"))=0,SUMPRODUCT(--('Repartition stock'!$A$6:$A$94="2026Q2"),--('Repartition stock'!$B$6:$B$94="AT"),--('Repartition stock'!$E$6:$E$94="Tranche"),--('Repartition stock'!$F$6:$F$94="> 1 000 €"),--('Repartition stock'!$J$6:$J$94="n.d."))>0),"n.d.",SUMPRODUCT(--('Repartition stock'!$A$6:$A$94="2026Q2"),--('Repartition stock'!$B$6:$B$94="AT"),--('Repartition stock'!$E$6:$E$94="Tranche"),--('Repartition stock'!$F$6:$F$94="> 1 000 €"),'Repartition stock'!$J$6:$J$94)) -> 7388.06 | AC11: =IF(OR(COUNT(X11,X12)<>2,X12=0),"n.d.",X11/X12) -> 0.054054054 | AE11: =IF(OR(COUNT(Z11,Z12)<>2,Z12=0),"n.d.",Z11/Z12) -> 0.61606749
R12: Total: | X12: =IF(COUNT(X7:X11)=5,SUM(X7:X11),"n.d.") -> 74 | Z12: =IF(COUNT(Z7:Z11)=5,SUM(Z7:Z11),"n.d.") -> 11992.29 | AC12: =IF(OR(NOT(ISNUMBER(X12)),X12=0),"n.d.",1) -> 1 | AE12: =IF(OR(NOT(ISNUMBER(Z12)),Z12=0),"n.d.",1) -> 1
R14: By date of positive balance | U14: <2018 | X14: =IF(OR(SUMPRODUCT(--('Repartition stock'!$A$6:$A$94="2026Q2"),--('Repartition stock'!$B$6:$B$94="AT"),--('Repartition stock'!$E$6:$E$94="Millésime"),--('Repartition stock'!$F$6:$F$94="<2018"))=0,SUMPRODUCT(--('Repartition stock'!$A$6:$A$94="2026Q2"),--('Repartition stock'!$B$6:$B$94="AT"),--('Repartition stock'!$E$6:$E$94="Millésime"),--('Repartition stock'!$F$6:$F$94="<2018"),--('Repartition stock'!$G$6:$G$94="n.d."))>0),"n.d.",SUMPRODUCT(--('Repartition stock'!$A$6:$A$94="2026Q2"),--('Repartition stock'!$B$6:$B$94="AT"),--('Repartition stock'!$E$6:$E$94="Millésime"),--('Repartition stock'!$F$6:$F$94="<2018"),'Repartition stock'!$G$6:$G$94)) -> n.d. | Z14: =IF(OR(SUMPRODUCT(--('Repartition stock'!$A$6:$A$94="2026Q2"),--('Repartition stock'!$B$6:$B$94="AT"),--('Repartition stock'!$E$6:$E$94="Millésime"),--('Repartition stock'!$F$6:$F$94="<2018"))=0,SUMPRODUCT(--('Repartition stock'!$A$6:$A$94="2026Q2"),--('Repartition stock'!$B$6:$B$94="AT"),--('Repartition stock'!$E$6:$E$94="Millésime"),--('Repartition stock'!$F$6:$F$94="<2018"),--('Repartition stock'!$J$6:$J$94="n.d."))>0),"n.d.",SUMPRODUCT(--('Repartition stock'!$A$6:$A$94="2026Q2"),--('Repartition stock'!$B$6:$B$94="AT"),--('Repartition stock'!$E$6:$E$94="Millésime"),--('Repartition stock'!$F$6:$F$94="<2018"),'Repartition stock'!$J$6:$J$94)) -> n.d. | AC14: =IF(OR(COUNT(X14,X24)<>2,X24=0),"n.d.",X14/X24) -> n.d. | AE14: =IF(OR(COUNT(Z14,Z24)<>2,Z24=0),"n.d.",Z14/Z24) -> n.d.
U15: 2018 | X15: =IF(OR(SUMPRODUCT(--('Repartition stock'!$A$6:$A$94="2026Q2"),--('Repartition stock'!$B$6:$B$94="AT"),--('Repartition stock'!$E$6:$E$94="Millésime"),--('Repartition stock'!$F$6:$F$94="2018"))=0,SUMPRODUCT(--('Repartition stock'!$A$6:$A$94="2026Q2"),--('Repartition stock'!$B$6:$B$94="AT"),--('Repartition stock'!$E$6:$E$94="Millésime"),--('Repartition stock'!$F$6:$F$94="2018"),--('Repartition stock'!$G$6:$G$94="n.d."))>0),"n.d.",SUMPRODUCT(--('Repartition stock'!$A$6:$A$94="2026Q2"),--('Repartition stock'!$B$6:$B$94="AT"),--('Repartition stock'!$E$6:$E$94="Millésime"),--('Repartition stock'!$F$6:$F$94="2018"),'Repartition stock'!$G$6:$G$94)) -> n.d. | Z15: =IF(OR(SUMPRODUCT(--('Repartition stock'!$A$6:$A$94="2026Q2"),--('Repartition stock'!$B$6:$B$94="AT"),--('Repartition stock'!$E$6:$E$94="Millésime"),--('Repartition stock'!$F$6:$F$94="2018"))=0,SUMPRODUCT(--('Repartition stock'!$A$6:$A$94="2026Q2"),--('Repartition stock'!$B$6:$B$94="AT"),--('Repartition stock'!$E$6:$E$94="Millésime"),--('Repartition stock'!$F$6:$F$94="2018"),--('Repartition stock'!$J$6:$J$94="n.d."))>0),"n.d.",SUMPRODUCT(--('Repartition stock'!$A$6:$A$94="2026Q2"),--('Repartition stock'!$B$6:$B$94="AT"),--('Repartition stock'!$E$6:$E$94="Millésime"),--('Repartition stock'!$F$6:$F$94="2018"),'Repartition stock'!$J$6:$J$94)) -> n.d. | AC15: =IF(OR(COUNT(X15,X24)<>2,X24=0),"n.d.",X15/X24) -> n.d. | AE15: =IF(OR(COUNT(Z15,Z24)<>2,Z24=0),"n.d.",Z15/Z24) -> n.d.
U16: 2019 | X16: =IF(OR(SUMPRODUCT(--('Repartition stock'!$A$6:$A$94="2026Q2"),--('Repartition stock'!$B$6:$B$94="AT"),--('Repartition stock'!$E$6:$E$94="Millésime"),--('Repartition stock'!$F$6:$F$94="2019"))=0,SUMPRODUCT(--('Repartition stock'!$A$6:$A$94="2026Q2"),--('Repartition stock'!$B$6:$B$94="AT"),--('Repartition stock'!$E$6:$E$94="Millésime"),--('Repartition stock'!$F$6:$F$94="2019"),--('Repartition stock'!$G$6:$G$94="n.d."))>0),"n.d.",SUMPRODUCT(--('Repartition stock'!$A$6:$A$94="2026Q2"),--('Repartition stock'!$B$6:$B$94="AT"),--('Repartition stock'!$E$6:$E$94="Millésime"),--('Repartition stock'!$F$6:$F$94="2019"),'Repartition stock'!$G$6:$G$94)) -> 1 | Z16: =IF(OR(SUMPRODUCT(--('Repartition stock'!$A$6:$A$94="2026Q2"),--('Repartition stock'!$B$6:$B$94="AT"),--('Repartition stock'!$E$6:$E$94="Millésime"),--('Repartition stock'!$F$6:$F$94="2019"))=0,SUMPRODUCT(--('Repartition stock'!$A$6:$A$94="2026Q2"),--('Repartition stock'!$B$6:$B$94="AT"),--('Repartition stock'!$E$6:$E$94="Millésime"),--('Repartition stock'!$F$6:$F$94="2019"),--('Repartition stock'!$J$6:$J$94="n.d."))>0),"n.d.",SUMPRODUCT(--('Repartition stock'!$A$6:$A$94="2026Q2"),--('Repartition stock'!$B$6:$B$94="AT"),--('Repartition stock'!$E$6:$E$94="Millésime"),--('Repartition stock'!$F$6:$F$94="2019"),'Repartition stock'!$J$6:$J$94)) -> 2314.9 | AC16: =IF(OR(COUNT(X16,X24)<>2,X24=0),"n.d.",X16/X24) -> 0.013513514 | AE16: =IF(OR(COUNT(Z16,Z24)<>2,Z24=0),"n.d.",Z16/Z24) -> 0.19303236
U17: 2020 | X17: =IF(OR(SUMPRODUCT(--('Repartition stock'!$A$6:$A$94="2026Q2"),--('Repartition stock'!$B$6:$B$94="AT"),--('Repartition stock'!$E$6:$E$94="Millésime"),--('Repartition stock'!$F$6:$F$94="2020"))=0,SUMPRODUCT(--('Repartition stock'!$A$6:$A$94="2026Q2"),--('Repartition stock'!$B$6:$B$94="AT"),--('Repartition stock'!$E$6:$E$94="Millésime"),--('Repartition stock'!$F$6:$F$94="2020"),--('Repartition stock'!$G$6:$G$94="n.d."))>0),"n.d.",SUMPRODUCT(--('Repartition stock'!$A$6:$A$94="2026Q2"),--('Repartition stock'!$B$6:$B$94="AT"),--('Repartition stock'!$E$6:$E$94="Millésime"),--('Repartition stock'!$F$6:$F$94="2020"),'Repartition stock'!$G$6:$G$94)) -> 0 | Z17: =IF(OR(SUMPRODUCT(--('Repartition stock'!$A$6:$A$94="2026Q2"),--('Repartition stock'!$B$6:$B$94="AT"),--('Repartition stock'!$E$6:$E$94="Millésime"),--('Repartition stock'!$F$6:$F$94="2020"))=0,SUMPRODUCT(--('Repartition stock'!$A$6:$A$94="2026Q2"),--('Repartition stock'!$B$6:$B$94="AT"),--('Repartition stock'!$E$6:$E$94="Millésime"),--('Repartition stock'!$F$6:$F$94="2020"),--('Repartition stock'!$J$6:$J$94="n.d."))>0),"n.d.",SUMPRODUCT(--('Repartition stock'!$A$6:$A$94="2026Q2"),--('Repartition stock'!$B$6:$B$94="AT"),--('Repartition stock'!$E$6:$E$94="Millésime"),--('Repartition stock'!$F$6:$F$94="2020"),'Repartition stock'!$J$6:$J$94)) -> 0 | AC17: =IF(OR(COUNT(X17,X24)<>2,X24=0),"n.d.",X17/X24) -> 0 | AE17: =IF(OR(COUNT(Z17,Z24)<>2,Z24=0),"n.d.",Z17/Z24) -> 0
U18: 2021 | X18: =IF(OR(SUMPRODUCT(--('Repartition stock'!$A$6:$A$94="2026Q2"),--('Repartition stock'!$B$6:$B$94="AT"),--('Repartition stock'!$E$6:$E$94="Millésime"),--('Repartition stock'!$F$6:$F$94="2021"))=0,SUMPRODUCT(--('Repartition stock'!$A$6:$A$94="2026Q2"),--('Repartition stock'!$B$6:$B$94="AT"),--('Repartition stock'!$E$6:$E$94="Millésime"),--('Repartition stock'!$F$6:$F$94="2021"),--('Repartition stock'!$G$6:$G$94="n.d."))>0),"n.d.",SUMPRODUCT(--('Repartition stock'!$A$6:$A$94="2026Q2"),--('Repartition stock'!$B$6:$B$94="AT"),--('Repartition stock'!$E$6:$E$94="Millésime"),--('Repartition stock'!$F$6:$F$94="2021"),'Repartition stock'!$G$6:$G$94)) -> 1 | Z18: =IF(OR(SUMPRODUCT(--('Repartition stock'!$A$6:$A$94="2026Q2"),--('Repartition stock'!$B$6:$B$94="AT"),--('Repartition stock'!$E$6:$E$94="Millésime"),--('Repartition stock'!$F$6:$F$94="2021"))=0,SUMPRODUCT(--('Repartition stock'!$A$6:$A$94="2026Q2"),--('Repartition stock'!$B$6:$B$94="AT"),--('Repartition stock'!$E$6:$E$94="Millésime"),--('Repartition stock'!$F$6:$F$94="2021"),--('Repartition stock'!$J$6:$J$94="n.d."))>0),"n.d.",SUMPRODUCT(--('Repartition stock'!$A$6:$A$94="2026Q2"),--('Repartition stock'!$B$6:$B$94="AT"),--('Repartition stock'!$E$6:$E$94="Millésime"),--('Repartition stock'!$F$6:$F$94="2021"),'Repartition stock'!$J$6:$J$94)) -> 81.01 | AC18: =IF(OR(COUNT(X18,X24)<>2,X24=0),"n.d.",X18/X24) -> 0.013513514 | AE18: =IF(OR(COUNT(Z18,Z24)<>2,Z24=0),"n.d.",Z18/Z24) -> 0.0067551735
U19: 2022 | X19: =IF(OR(SUMPRODUCT(--('Repartition stock'!$A$6:$A$94="2026Q2"),--('Repartition stock'!$B$6:$B$94="AT"),--('Repartition stock'!$E$6:$E$94="Millésime"),--('Repartition stock'!$F$6:$F$94="2022"))=0,SUMPRODUCT(--('Repartition stock'!$A$6:$A$94="2026Q2"),--('Repartition stock'!$B$6:$B$94="AT"),--('Repartition stock'!$E$6:$E$94="Millésime"),--('Repartition stock'!$F$6:$F$94="2022"),--('Repartition stock'!$G$6:$G$94="n.d."))>0),"n.d.",SUMPRODUCT(--('Repartition stock'!$A$6:$A$94="2026Q2"),--('Repartition stock'!$B$6:$B$94="AT"),--('Repartition stock'!$E$6:$E$94="Millésime"),--('Repartition stock'!$F$6:$F$94="2022"),'Repartition stock'!$G$6:$G$94)) -> 0 | Z19: =IF(OR(SUMPRODUCT(--('Repartition stock'!$A$6:$A$94="2026Q2"),--('Repartition stock'!$B$6:$B$94="AT"),--('Repartition stock'!$E$6:$E$94="Millésime"),--('Repartition stock'!$F$6:$F$94="2022"))=0,SUMPRODUCT(--('Repartition stock'!$A$6:$A$94="2026Q2"),--('Repartition stock'!$B$6:$B$94="AT"),--('Repartition stock'!$E$6:$E$94="Millésime"),--('Repartition stock'!$F$6:$F$94="2022"),--('Repartition stock'!$J$6:$J$94="n.d."))>0),"n.d.",SUMPRODUCT(--('Repartition stock'!$A$6:$A$94="2026Q2"),--('Repartition stock'!$B$6:$B$94="AT"),--('Repartition stock'!$E$6:$E$94="Millésime"),--('Repartition stock'!$F$6:$F$94="2022"),'Repartition stock'!$J$6:$J$94)) -> 0 | AC19: =IF(OR(COUNT(X19,X24)<>2,X24=0),"n.d.",X19/X24) -> 0 | AE19: =IF(OR(COUNT(Z19,Z24)<>2,Z24=0),"n.d.",Z19/Z24) -> 0
U20: 2023 | X20: =IF(OR(SUMPRODUCT(--('Repartition stock'!$A$6:$A$94="2026Q2"),--('Repartition stock'!$B$6:$B$94="AT"),--('Repartition stock'!$E$6:$E$94="Millésime"),--('Repartition stock'!$F$6:$F$94="2023"))=0,SUMPRODUCT(--('Repartition stock'!$A$6:$A$94="2026Q2"),--('Repartition stock'!$B$6:$B$94="AT"),--('Repartition stock'!$E$6:$E$94="Millésime"),--('Repartition stock'!$F$6:$F$94="2023"),--('Repartition stock'!$G$6:$G$94="n.d."))>0),"n.d.",SUMPRODUCT(--('Repartition stock'!$A$6:$A$94="2026Q2"),--('Repartition stock'!$B$6:$B$94="AT"),--('Repartition stock'!$E$6:$E$94="Millésime"),--('Repartition stock'!$F$6:$F$94="2023"),'Repartition stock'!$G$6:$G$94)) -> 1 | Z20: =IF(OR(SUMPRODUCT(--('Repartition stock'!$A$6:$A$94="2026Q2"),--('Repartition stock'!$B$6:$B$94="AT"),--('Repartition stock'!$E$6:$E$94="Millésime"),--('Repartition stock'!$F$6:$F$94="2023"))=0,SUMPRODUCT(--('Repartition stock'!$A$6:$A$94="2026Q2"),--('Repartition stock'!$B$6:$B$94="AT"),--('Repartition stock'!$E$6:$E$94="Millésime"),--('Repartition stock'!$F$6:$F$94="2023"),--('Repartition stock'!$J$6:$J$94="n.d."))>0),"n.d.",SUMPRODUCT(--('Repartition stock'!$A$6:$A$94="2026Q2"),--('Repartition stock'!$B$6:$B$94="AT"),--('Repartition stock'!$E$6:$E$94="Millésime"),--('Repartition stock'!$F$6:$F$94="2023"),'Repartition stock'!$J$6:$J$94)) -> 47.06 | AC20: =IF(OR(COUNT(X20,X24)<>2,X24=0),"n.d.",X20/X24) -> 0.013513514 | AE20: =IF(OR(COUNT(Z20,Z24)<>2,Z24=0),"n.d.",Z20/Z24) -> 0.003924188
U21: 2024 | X21: =IF(OR(SUMPRODUCT(--('Repartition stock'!$A$6:$A$94="2026Q2"),--('Repartition stock'!$B$6:$B$94="AT"),--('Repartition stock'!$E$6:$E$94="Millésime"),--('Repartition stock'!$F$6:$F$94="2024"))=0,SUMPRODUCT(--('Repartition stock'!$A$6:$A$94="2026Q2"),--('Repartition stock'!$B$6:$B$94="AT"),--('Repartition stock'!$E$6:$E$94="Millésime"),--('Repartition stock'!$F$6:$F$94="2024"),--('Repartition stock'!$G$6:$G$94="n.d."))>0),"n.d.",SUMPRODUCT(--('Repartition stock'!$A$6:$A$94="2026Q2"),--('Repartition stock'!$B$6:$B$94="AT"),--('Repartition stock'!$E$6:$E$94="Millésime"),--('Repartition stock'!$F$6:$F$94="2024"),'Repartition stock'!$G$6:$G$94)) -> 3 | Z21: =IF(OR(SUMPRODUCT(--('Repartition stock'!$A$6:$A$94="2026Q2"),--('Repartition stock'!$B$6:$B$94="AT"),--('Repartition stock'!$E$6:$E$94="Millésime"),--('Repartition stock'!$F$6:$F$94="2024"))=0,SUMPRODUCT(--('Repartition stock'!$A$6:$A$94="2026Q2"),--('Repartition stock'!$B$6:$B$94="AT"),--('Repartition stock'!$E$6:$E$94="Millésime"),--('Repartition stock'!$F$6:$F$94="2024"),--('Repartition stock'!$J$6:$J$94="n.d."))>0),"n.d.",SUMPRODUCT(--('Repartition stock'!$A$6:$A$94="2026Q2"),--('Repartition stock'!$B$6:$B$94="AT"),--('Repartition stock'!$E$6:$E$94="Millésime"),--('Repartition stock'!$F$6:$F$94="2024"),'Repartition stock'!$J$6:$J$94)) -> 3734.12 | AC21: =IF(OR(COUNT(X21,X24)<>2,X24=0),"n.d.",X21/X24) -> 0.040540541 | AE21: =IF(OR(COUNT(Z21,Z24)<>2,Z24=0),"n.d.",Z21/Z24) -> 0.31137673
U22: 2025 | X22: =IF(OR(SUMPRODUCT(--('Repartition stock'!$A$6:$A$94="2026Q2"),--('Repartition stock'!$B$6:$B$94="AT"),--('Repartition stock'!$E$6:$E$94="Millésime"),--('Repartition stock'!$F$6:$F$94="2025"))=0,SUMPRODUCT(--('Repartition stock'!$A$6:$A$94="2026Q2"),--('Repartition stock'!$B$6:$B$94="AT"),--('Repartition stock'!$E$6:$E$94="Millésime"),--('Repartition stock'!$F$6:$F$94="2025"),--('Repartition stock'!$G$6:$G$94="n.d."))>0),"n.d.",SUMPRODUCT(--('Repartition stock'!$A$6:$A$94="2026Q2"),--('Repartition stock'!$B$6:$B$94="AT"),--('Repartition stock'!$E$6:$E$94="Millésime"),--('Repartition stock'!$F$6:$F$94="2025"),'Repartition stock'!$G$6:$G$94)) -> 3 | Z22: =IF(OR(SUMPRODUCT(--('Repartition stock'!$A$6:$A$94="2026Q2"),--('Repartition stock'!$B$6:$B$94="AT"),--('Repartition stock'!$E$6:$E$94="Millésime"),--('Repartition stock'!$F$6:$F$94="2025"))=0,SUMPRODUCT(--('Repartition stock'!$A$6:$A$94="2026Q2"),--('Repartition stock'!$B$6:$B$94="AT"),--('Repartition stock'!$E$6:$E$94="Millésime"),--('Repartition stock'!$F$6:$F$94="2025"),--('Repartition stock'!$J$6:$J$94="n.d."))>0),"n.d.",SUMPRODUCT(--('Repartition stock'!$A$6:$A$94="2026Q2"),--('Repartition stock'!$B$6:$B$94="AT"),--('Repartition stock'!$E$6:$E$94="Millésime"),--('Repartition stock'!$F$6:$F$94="2025"),'Repartition stock'!$J$6:$J$94)) -> 429.88 | AC22: =IF(OR(COUNT(X22,X24)<>2,X24=0),"n.d.",X22/X24) -> 0.040540541 | AE22: =IF(OR(COUNT(Z22,Z24)<>2,Z24=0),"n.d.",Z22/Z24) -> 0.035846365
U23: 2026 | X23: =IF(OR(SUMPRODUCT(--('Repartition stock'!$A$6:$A$94="2026Q2"),--('Repartition stock'!$B$6:$B$94="AT"),--('Repartition stock'!$E$6:$E$94="Millésime"),--('Repartition stock'!$F$6:$F$94="2026"))=0,SUMPRODUCT(--('Repartition stock'!$A$6:$A$94="2026Q2"),--('Repartition stock'!$B$6:$B$94="AT"),--('Repartition stock'!$E$6:$E$94="Millésime"),--('Repartition stock'!$F$6:$F$94="2026"),--('Repartition stock'!$G$6:$G$94="n.d."))>0),"n.d.",SUMPRODUCT(--('Repartition stock'!$A$6:$A$94="2026Q2"),--('Repartition stock'!$B$6:$B$94="AT"),--('Repartition stock'!$E$6:$E$94="Millésime"),--('Repartition stock'!$F$6:$F$94="2026"),'Repartition stock'!$G$6:$G$94)) -> 65 | Z23: =IF(OR(SUMPRODUCT(--('Repartition stock'!$A$6:$A$94="2026Q2"),--('Repartition stock'!$B$6:$B$94="AT"),--('Repartition stock'!$E$6:$E$94="Millésime"),--('Repartition stock'!$F$6:$F$94="2026"))=0,SUMPRODUCT(--('Repartition stock'!$A$6:$A$94="2026Q2"),--('Repartition stock'!$B$6:$B$94="AT"),--('Repartition stock'!$E$6:$E$94="Millésime"),--('Repartition stock'!$F$6:$F$94="2026"),--('Repartition stock'!$J$6:$J$94="n.d."))>0),"n.d.",SUMPRODUCT(--('Repartition stock'!$A$6:$A$94="2026Q2"),--('Repartition stock'!$B$6:$B$94="AT"),--('Repartition stock'!$E$6:$E$94="Millésime"),--('Repartition stock'!$F$6:$F$94="2026"),'Repartition stock'!$J$6:$J$94)) -> 5385.32 | AC23: =IF(OR(COUNT(X23,X24)<>2,X24=0),"n.d.",X23/X24) -> 0.87837838 | AE23: =IF(OR(COUNT(Z23,Z24)<>2,Z24=0),"n.d.",Z23/Z24) -> 0.44906519
R24: Total: | X24: ='Presentation inputs'!D7 -> 74 | Z24: =IF(ISNUMBER('Presentation inputs'!E7),'Presentation inputs'!E7/(IF(OR(COUNTIFS('Consolidation'!$A$6:$A$11,"2026Q2",'Consolidation'!$B$6:$B$11,"AT")<>1,COUNTIFS('Consolidation'!$A$6:$A$11,"2026Q2",'Consolidation'!$B$6:$B$11,"AT",'Consolidation'!$E$6:$E$11,"n.d.")>0),"n.d.",SUMIFS('Consolidation'!$E$6:$E$11,'Consolidation'!$A$6:$A$11,"2026Q2",'Consolidation'!$B$6:$B$11,"AT"))),"n.d.") -> 11992.29 | AC24: =IF(OR(NOT(ISNUMBER(X24)),X24=0),"n.d.",1) -> 1 | AE24: =IF(OR(NOT(ISNUMBER(Z24)),Z24=0),"n.d.",1) -> 1
R26: Some vintage details are missing. The reported total is retained.
B30: ="Average monthly new flow: "&IF(ISNUMBER('GraphData'!A86),TEXT('GraphData'!A86,"#,##0"),"n.d.")&" EUR. Average balance per contract: "&IF(ISNUMBER('GraphData'!B86),TEXT('GraphData'!B86,"#,##0"),"n.d.")&" EUR." -> Average monthly new flow: 9,124 EUR. Average balance per contract: 207 EUR.
B32: ="Oldest cohort (M-5): "&IF(ISNUMBER('GraphData'!C86),TEXT('GraphData'!C86,"0.0%"),"n.d.")&" treated in amount and "&IF(ISNUMBER('GraphData'!D86),TEXT('GraphData'!D86,"0.0%"),"n.d.")&" in number." -> Oldest cohort (M-5): 90.1% treated in amount and 77.3% in number.
B34: ="Stock to process: "&IF(ISNUMBER('GraphData'!E86),TEXT('GraphData'!E86,"#,##0"),"n.d.")&" EUR. Identified stock: "&IF(ISNUMBER('GraphData'!F86),TEXT('GraphData'!F86,"#,##0"),"n.d.")&" EUR." -> Stock to process: 11,992 EUR. Identified stock: 11,992 EUR.
B36: Prior-quarter comparison unavailable: no 2026Q1 source snapshot has been imported.
B42: Positive Balance 2026Q2 Source: country workbooks and Taux.xlsx Internal

Sheet IT Italy
B2: Italy | R2: STOCK OF POSITIVE BALANCES to be processed (KPI_3) | X2: 46203
X3: Number of contracts | Z3: Total amount EUR | AC3: % in number | AE3: % in amount
B5: Reporting at 30 June 2026. Six monthly cohorts.
R7: By step of amount | U7: 0 - 1 € | X7: =IF(OR(SUMPRODUCT(--('Repartition stock'!$A$6:$A$94="2026Q2"),--('Repartition stock'!$B$6:$B$94="IT"),--('Repartition stock'!$E$6:$E$94="Tranche"),--('Repartition stock'!$F$6:$F$94="0 - 1 €"))=0,SUMPRODUCT(--('Repartition stock'!$A$6:$A$94="2026Q2"),--('Repartition stock'!$B$6:$B$94="IT"),--('Repartition stock'!$E$6:$E$94="Tranche"),--('Repartition stock'!$F$6:$F$94="0 - 1 €"),--('Repartition stock'!$G$6:$G$94="n.d."))>0),"n.d.",SUMPRODUCT(--('Repartition stock'!$A$6:$A$94="2026Q2"),--('Repartition stock'!$B$6:$B$94="IT"),--('Repartition stock'!$E$6:$E$94="Tranche"),--('Repartition stock'!$F$6:$F$94="0 - 1 €"),'Repartition stock'!$G$6:$G$94)) -> 883 | Z7: =IF(OR(SUMPRODUCT(--('Repartition stock'!$A$6:$A$94="2026Q2"),--('Repartition stock'!$B$6:$B$94="IT"),--('Repartition stock'!$E$6:$E$94="Tranche"),--('Repartition stock'!$F$6:$F$94="0 - 1 €"))=0,SUMPRODUCT(--('Repartition stock'!$A$6:$A$94="2026Q2"),--('Repartition stock'!$B$6:$B$94="IT"),--('Repartition stock'!$E$6:$E$94="Tranche"),--('Repartition stock'!$F$6:$F$94="0 - 1 €"),--('Repartition stock'!$J$6:$J$94="n.d."))>0),"n.d.",SUMPRODUCT(--('Repartition stock'!$A$6:$A$94="2026Q2"),--('Repartition stock'!$B$6:$B$94="IT"),--('Repartition stock'!$E$6:$E$94="Tranche"),--('Repartition stock'!$F$6:$F$94="0 - 1 €"),'Repartition stock'!$J$6:$J$94)) -> 415.76 | AC7: =IF(OR(COUNT(X7,X12)<>2,X12=0),"n.d.",X7/X12) -> 0.15781948 | AE7: =IF(OR(COUNT(Z7,Z12)<>2,Z12=0),"n.d.",Z7/Z12) -> 0.00052799866
U8: 1 - 10 € | X8: =IF(OR(SUMPRODUCT(--('Repartition stock'!$A$6:$A$94="2026Q2"),--('Repartition stock'!$B$6:$B$94="IT"),--('Repartition stock'!$E$6:$E$94="Tranche"),--('Repartition stock'!$F$6:$F$94="1 - 10 €"))=0,SUMPRODUCT(--('Repartition stock'!$A$6:$A$94="2026Q2"),--('Repartition stock'!$B$6:$B$94="IT"),--('Repartition stock'!$E$6:$E$94="Tranche"),--('Repartition stock'!$F$6:$F$94="1 - 10 €"),--('Repartition stock'!$G$6:$G$94="n.d."))>0),"n.d.",SUMPRODUCT(--('Repartition stock'!$A$6:$A$94="2026Q2"),--('Repartition stock'!$B$6:$B$94="IT"),--('Repartition stock'!$E$6:$E$94="Tranche"),--('Repartition stock'!$F$6:$F$94="1 - 10 €"),'Repartition stock'!$G$6:$G$94)) -> 2368 | Z8: =IF(OR(SUMPRODUCT(--('Repartition stock'!$A$6:$A$94="2026Q2"),--('Repartition stock'!$B$6:$B$94="IT"),--('Repartition stock'!$E$6:$E$94="Tranche"),--('Repartition stock'!$F$6:$F$94="1 - 10 €"))=0,SUMPRODUCT(--('Repartition stock'!$A$6:$A$94="2026Q2"),--('Repartition stock'!$B$6:$B$94="IT"),--('Repartition stock'!$E$6:$E$94="Tranche"),--('Repartition stock'!$F$6:$F$94="1 - 10 €"),--('Repartition stock'!$J$6:$J$94="n.d."))>0),"n.d.",SUMPRODUCT(--('Repartition stock'!$A$6:$A$94="2026Q2"),--('Repartition stock'!$B$6:$B$94="IT"),--('Repartition stock'!$E$6:$E$94="Tranche"),--('Repartition stock'!$F$6:$F$94="1 - 10 €"),'Repartition stock'!$J$6:$J$94)) -> 7036.99 | AC8: =IF(OR(COUNT(X8,X12)<>2,X12=0),"n.d.",X8/X12) -> 0.42323503 | AE8: =IF(OR(COUNT(Z8,Z12)<>2,Z12=0),"n.d.",Z8/Z12) -> 0.0089366974
U9: 10 - 100 € | X9: =IF(OR(SUMPRODUCT(--('Repartition stock'!$A$6:$A$94="2026Q2"),--('Repartition stock'!$B$6:$B$94="IT"),--('Repartition stock'!$E$6:$E$94="Tranche"),--('Repartition stock'!$F$6:$F$94="10 - 100 €"))=0,SUMPRODUCT(--('Repartition stock'!$A$6:$A$94="2026Q2"),--('Repartition stock'!$B$6:$B$94="IT"),--('Repartition stock'!$E$6:$E$94="Tranche"),--('Repartition stock'!$F$6:$F$94="10 - 100 €"),--('Repartition stock'!$G$6:$G$94="n.d."))>0),"n.d.",SUMPRODUCT(--('Repartition stock'!$A$6:$A$94="2026Q2"),--('Repartition stock'!$B$6:$B$94="IT"),--('Repartition stock'!$E$6:$E$94="Tranche"),--('Repartition stock'!$F$6:$F$94="10 - 100 €"),'Repartition stock'!$G$6:$G$94)) -> 490 | Z9: =IF(OR(SUMPRODUCT(--('Repartition stock'!$A$6:$A$94="2026Q2"),--('Repartition stock'!$B$6:$B$94="IT"),--('Repartition stock'!$E$6:$E$94="Tranche"),--('Repartition stock'!$F$6:$F$94="10 - 100 €"))=0,SUMPRODUCT(--('Repartition stock'!$A$6:$A$94="2026Q2"),--('Repartition stock'!$B$6:$B$94="IT"),--('Repartition stock'!$E$6:$E$94="Tranche"),--('Repartition stock'!$F$6:$F$94="10 - 100 €"),--('Repartition stock'!$J$6:$J$94="n.d."))>0),"n.d.",SUMPRODUCT(--('Repartition stock'!$A$6:$A$94="2026Q2"),--('Repartition stock'!$B$6:$B$94="IT"),--('Repartition stock'!$E$6:$E$94="Tranche"),--('Repartition stock'!$F$6:$F$94="10 - 100 €"),'Repartition stock'!$J$6:$J$94)) -> 22684.66 | AC9: =IF(OR(COUNT(X9,X12)<>2,X12=0),"n.d.",X9/X12) -> 0.087578195 | AE9: =IF(OR(COUNT(Z9,Z12)<>2,Z12=0),"n.d.",Z9/Z12) -> 0.028808616
U10: 100 - 1 000 € | X10: =IF(OR(SUMPRODUCT(--('Repartition stock'!$A$6:$A$94="2026Q2"),--('Repartition stock'!$B$6:$B$94="IT"),--('Repartition stock'!$E$6:$E$94="Tranche"),--('Repartition stock'!$F$6:$F$94="100 - 1 000 €"))=0,SUMPRODUCT(--('Repartition stock'!$A$6:$A$94="2026Q2"),--('Repartition stock'!$B$6:$B$94="IT"),--('Repartition stock'!$E$6:$E$94="Tranche"),--('Repartition stock'!$F$6:$F$94="100 - 1 000 €"),--('Repartition stock'!$G$6:$G$94="n.d."))>0),"n.d.",SUMPRODUCT(--('Repartition stock'!$A$6:$A$94="2026Q2"),--('Repartition stock'!$B$6:$B$94="IT"),--('Repartition stock'!$E$6:$E$94="Tranche"),--('Repartition stock'!$F$6:$F$94="100 - 1 000 €"),'Repartition stock'!$G$6:$G$94)) -> 1755 | Z10: =IF(OR(SUMPRODUCT(--('Repartition stock'!$A$6:$A$94="2026Q2"),--('Repartition stock'!$B$6:$B$94="IT"),--('Repartition stock'!$E$6:$E$94="Tranche"),--('Repartition stock'!$F$6:$F$94="100 - 1 000 €"))=0,SUMPRODUCT(--('Repartition stock'!$A$6:$A$94="2026Q2"),--('Repartition stock'!$B$6:$B$94="IT"),--('Repartition stock'!$E$6:$E$94="Tranche"),--('Repartition stock'!$F$6:$F$94="100 - 1 000 €"),--('Repartition stock'!$J$6:$J$94="n.d."))>0),"n.d.",SUMPRODUCT(--('Repartition stock'!$A$6:$A$94="2026Q2"),--('Repartition stock'!$B$6:$B$94="IT"),--('Repartition stock'!$E$6:$E$94="Tranche"),--('Repartition stock'!$F$6:$F$94="100 - 1 000 €"),'Repartition stock'!$J$6:$J$94)) -> 510950.87 | AC10: =IF(OR(COUNT(X10,X12)<>2,X12=0),"n.d.",X10/X12) -> 0.31367292 | AE10: =IF(OR(COUNT(Z10,Z12)<>2,Z12=0),"n.d.",Z10/Z12) -> 0.64888728
U11: > 1 000 € | X11: =IF(OR(SUMPRODUCT(--('Repartition stock'!$A$6:$A$94="2026Q2"),--('Repartition stock'!$B$6:$B$94="IT"),--('Repartition stock'!$E$6:$E$94="Tranche"),--('Repartition stock'!$F$6:$F$94="> 1 000 €"))=0,SUMPRODUCT(--('Repartition stock'!$A$6:$A$94="2026Q2"),--('Repartition stock'!$B$6:$B$94="IT"),--('Repartition stock'!$E$6:$E$94="Tranche"),--('Repartition stock'!$F$6:$F$94="> 1 000 €"),--('Repartition stock'!$G$6:$G$94="n.d."))>0),"n.d.",SUMPRODUCT(--('Repartition stock'!$A$6:$A$94="2026Q2"),--('Repartition stock'!$B$6:$B$94="IT"),--('Repartition stock'!$E$6:$E$94="Tranche"),--('Repartition stock'!$F$6:$F$94="> 1 000 €"),'Repartition stock'!$G$6:$G$94)) -> 99 | Z11: =IF(OR(SUMPRODUCT(--('Repartition stock'!$A$6:$A$94="2026Q2"),--('Repartition stock'!$B$6:$B$94="IT"),--('Repartition stock'!$E$6:$E$94="Tranche"),--('Repartition stock'!$F$6:$F$94="> 1 000 €"))=0,SUMPRODUCT(--('Repartition stock'!$A$6:$A$94="2026Q2"),--('Repartition stock'!$B$6:$B$94="IT"),--('Repartition stock'!$E$6:$E$94="Tranche"),--('Repartition stock'!$F$6:$F$94="> 1 000 €"),--('Repartition stock'!$J$6:$J$94="n.d."))>0),"n.d.",SUMPRODUCT(--('Repartition stock'!$A$6:$A$94="2026Q2"),--('Repartition stock'!$B$6:$B$94="IT"),--('Repartition stock'!$E$6:$E$94="Tranche"),--('Repartition stock'!$F$6:$F$94="> 1 000 €"),'Repartition stock'!$J$6:$J$94)) -> 246337.96 | AC11: =IF(OR(COUNT(X11,X12)<>2,X12=0),"n.d.",X11/X12) -> 0.01769437 | AE11: =IF(OR(COUNT(Z11,Z12)<>2,Z12=0),"n.d.",Z11/Z12) -> 0.31283941
R12: Total: | X12: =IF(COUNT(X7:X11)=5,SUM(X7:X11),"n.d.") -> 5595 | Z12: =IF(COUNT(Z7:Z11)=5,SUM(Z7:Z11),"n.d.") -> 787426.24 | AC12: =IF(OR(NOT(ISNUMBER(X12)),X12=0),"n.d.",1) -> 1 | AE12: =IF(OR(NOT(ISNUMBER(Z12)),Z12=0),"n.d.",1) -> 1
R14: By date of positive balance | U14: <2018 | X14: =IF(OR(SUMPRODUCT(--('Repartition stock'!$A$6:$A$94="2026Q2"),--('Repartition stock'!$B$6:$B$94="IT"),--('Repartition stock'!$E$6:$E$94="Millésime"),--('Repartition stock'!$F$6:$F$94="<2018"))=0,SUMPRODUCT(--('Repartition stock'!$A$6:$A$94="2026Q2"),--('Repartition stock'!$B$6:$B$94="IT"),--('Repartition stock'!$E$6:$E$94="Millésime"),--('Repartition stock'!$F$6:$F$94="<2018"),--('Repartition stock'!$G$6:$G$94="n.d."))>0),"n.d.",SUMPRODUCT(--('Repartition stock'!$A$6:$A$94="2026Q2"),--('Repartition stock'!$B$6:$B$94="IT"),--('Repartition stock'!$E$6:$E$94="Millésime"),--('Repartition stock'!$F$6:$F$94="<2018"),'Repartition stock'!$G$6:$G$94)) -> n.d. | Z14: =IF(OR(SUMPRODUCT(--('Repartition stock'!$A$6:$A$94="2026Q2"),--('Repartition stock'!$B$6:$B$94="IT"),--('Repartition stock'!$E$6:$E$94="Millésime"),--('Repartition stock'!$F$6:$F$94="<2018"))=0,SUMPRODUCT(--('Repartition stock'!$A$6:$A$94="2026Q2"),--('Repartition stock'!$B$6:$B$94="IT"),--('Repartition stock'!$E$6:$E$94="Millésime"),--('Repartition stock'!$F$6:$F$94="<2018"),--('Repartition stock'!$J$6:$J$94="n.d."))>0),"n.d.",SUMPRODUCT(--('Repartition stock'!$A$6:$A$94="2026Q2"),--('Repartition stock'!$B$6:$B$94="IT"),--('Repartition stock'!$E$6:$E$94="Millésime"),--('Repartition stock'!$F$6:$F$94="<2018"),'Repartition stock'!$J$6:$J$94)) -> n.d. | AC14: =IF(OR(COUNT(X14,X24)<>2,X24=0),"n.d.",X14/X24) -> n.d. | AE14: =IF(OR(COUNT(Z14,Z24)<>2,Z24=0),"n.d.",Z14/Z24) -> n.d.
U15: 2018 | X15: =IF(OR(SUMPRODUCT(--('Repartition stock'!$A$6:$A$94="2026Q2"),--('Repartition stock'!$B$6:$B$94="IT"),--('Repartition stock'!$E$6:$E$94="Millésime"),--('Repartition stock'!$F$6:$F$94="2018"))=0,SUMPRODUCT(--('Repartition stock'!$A$6:$A$94="2026Q2"),--('Repartition stock'!$B$6:$B$94="IT"),--('Repartition stock'!$E$6:$E$94="Millésime"),--('Repartition stock'!$F$6:$F$94="2018"),--('Repartition stock'!$G$6:$G$94="n.d."))>0),"n.d.",SUMPRODUCT(--('Repartition stock'!$A$6:$A$94="2026Q2"),--('Repartition stock'!$B$6:$B$94="IT"),--('Repartition stock'!$E$6:$E$94="Millésime"),--('Repartition stock'!$F$6:$F$94="2018"),'Repartition stock'!$G$6:$G$94)) -> n.d. | Z15: =IF(OR(SUMPRODUCT(--('Repartition stock'!$A$6:$A$94="2026Q2"),--('Repartition stock'!$B$6:$B$94="IT"),--('Repartition stock'!$E$6:$E$94="Millésime"),--('Repartition stock'!$F$6:$F$94="2018"))=0,SUMPRODUCT(--('Repartition stock'!$A$6:$A$94="2026Q2"),--('Repartition stock'!$B$6:$B$94="IT"),--('Repartition stock'!$E$6:$E$94="Millésime"),--('Repartition stock'!$F$6:$F$94="2018"),--('Repartition stock'!$J$6:$J$94="n.d."))>0),"n.d.",SUMPRODUCT(--('Repartition stock'!$A$6:$A$94="2026Q2"),--('Repartition stock'!$B$6:$B$94="IT"),--('Repartition stock'!$E$6:$E$94="Millésime"),--('Repartition stock'!$F$6:$F$94="2018"),'Repartition stock'!$J$6:$J$94)) -> n.d. | AC15: =IF(OR(COUNT(X15,X24)<>2,X24=0),"n.d.",X15/X24) -> n.d. | AE15: =IF(OR(COUNT(Z15,Z24)<>2,Z24=0),"n.d.",Z15/Z24) -> n.d.
U16: 2019 | X16: =IF(OR(SUMPRODUCT(--('Repartition stock'!$A$6:$A$94="2026Q2"),--('Repartition stock'!$B$6:$B$94="IT"),--('Repartition stock'!$E$6:$E$94="Millésime"),--('Repartition stock'!$F$6:$F$94="2019"))=0,SUMPRODUCT(--('Repartition stock'!$A$6:$A$94="2026Q2"),--('Repartition stock'!$B$6:$B$94="IT"),--('Repartition stock'!$E$6:$E$94="Millésime"),--('Repartition stock'!$F$6:$F$94="2019"),--('Repartition stock'!$G$6:$G$94="n.d."))>0),"n.d.",SUMPRODUCT(--('Repartition stock'!$A$6:$A$94="2026Q2"),--('Repartition stock'!$B$6:$B$94="IT"),--('Repartition stock'!$E$6:$E$94="Millésime"),--('Repartition stock'!$F$6:$F$94="2019"),'Repartition stock'!$G$6:$G$94)) -> n.d. | Z16: =IF(OR(SUMPRODUCT(--('Repartition stock'!$A$6:$A$94="2026Q2"),--('Repartition stock'!$B$6:$B$94="IT"),--('Repartition stock'!$E$6:$E$94="Millésime"),--('Repartition stock'!$F$6:$F$94="2019"))=0,SUMPRODUCT(--('Repartition stock'!$A$6:$A$94="2026Q2"),--('Repartition stock'!$B$6:$B$94="IT"),--('Repartition stock'!$E$6:$E$94="Millésime"),--('Repartition stock'!$F$6:$F$94="2019"),--('Repartition stock'!$J$6:$J$94="n.d."))>0),"n.d.",SUMPRODUCT(--('Repartition stock'!$A$6:$A$94="2026Q2"),--('Repartition stock'!$B$6:$B$94="IT"),--('Repartition stock'!$E$6:$E$94="Millésime"),--('Repartition stock'!$F$6:$F$94="2019"),'Repartition stock'!$J$6:$J$94)) -> n.d. | AC16: =IF(OR(COUNT(X16,X24)<>2,X24=0),"n.d.",X16/X24) -> n.d. | AE16: =IF(OR(COUNT(Z16,Z24)<>2,Z24=0),"n.d.",Z16/Z24) -> n.d.
U17: 2020 | X17: =IF(OR(SUMPRODUCT(--('Repartition stock'!$A$6:$A$94="2026Q2"),--('Repartition stock'!$B$6:$B$94="IT"),--('Repartition stock'!$E$6:$E$94="Millésime"),--('Repartition stock'!$F$6:$F$94="2020"))=0,SUMPRODUCT(--('Repartition stock'!$A$6:$A$94="2026Q2"),--('Repartition stock'!$B$6:$B$94="IT"),--('Repartition stock'!$E$6:$E$94="Millésime"),--('Repartition stock'!$F$6:$F$94="2020"),--('Repartition stock'!$G$6:$G$94="n.d."))>0),"n.d.",SUMPRODUCT(--('Repartition stock'!$A$6:$A$94="2026Q2"),--('Repartition stock'!$B$6:$B$94="IT"),--('Repartition stock'!$E$6:$E$94="Millésime"),--('Repartition stock'!$F$6:$F$94="2020"),'Repartition stock'!$G$6:$G$94)) -> n.d. | Z17: =IF(OR(SUMPRODUCT(--('Repartition stock'!$A$6:$A$94="2026Q2"),--('Repartition stock'!$B$6:$B$94="IT"),--('Repartition stock'!$E$6:$E$94="Millésime"),--('Repartition stock'!$F$6:$F$94="2020"))=0,SUMPRODUCT(--('Repartition stock'!$A$6:$A$94="2026Q2"),--('Repartition stock'!$B$6:$B$94="IT"),--('Repartition stock'!$E$6:$E$94="Millésime"),--('Repartition stock'!$F$6:$F$94="2020"),--('Repartition stock'!$J$6:$J$94="n.d."))>0),"n.d.",SUMPRODUCT(--('Repartition stock'!$A$6:$A$94="2026Q2"),--('Repartition stock'!$B$6:$B$94="IT"),--('Repartition stock'!$E$6:$E$94="Millésime"),--('Repartition stock'!$F$6:$F$94="2020"),'Repartition stock'!$J$6:$J$94)) -> n.d. | AC17: =IF(OR(COUNT(X17,X24)<>2,X24=0),"n.d.",X17/X24) -> n.d. | AE17: =IF(OR(COUNT(Z17,Z24)<>2,Z24=0),"n.d.",Z17/Z24) -> n.d.
U18: 2021 | X18: =IF(OR(SUMPRODUCT(--('Repartition stock'!$A$6:$A$94="2026Q2"),--('Repartition stock'!$B$6:$B$94="IT"),--('Repartition stock'!$E$6:$E$94="Millésime"),--('Repartition stock'!$F$6:$F$94="2021"))=0,SUMPRODUCT(--('Repartition stock'!$A$6:$A$94="2026Q2"),--('Repartition stock'!$B$6:$B$94="IT"),--('Repartition stock'!$E$6:$E$94="Millésime"),--('Repartition stock'!$F$6:$F$94="2021"),--('Repartition stock'!$G$6:$G$94="n.d."))>0),"n.d.",SUMPRODUCT(--('Repartition stock'!$A$6:$A$94="2026Q2"),--('Repartition stock'!$B$6:$B$94="IT"),--('Repartition stock'!$E$6:$E$94="Millésime"),--('Repartition stock'!$F$6:$F$94="2021"),'Repartition stock'!$G$6:$G$94)) -> n.d. | Z18: =IF(OR(SUMPRODUCT(--('Repartition stock'!$A$6:$A$94="2026Q2"),--('Repartition stock'!$B$6:$B$94="IT"),--('Repartition stock'!$E$6:$E$94="Millésime"),--('Repartition stock'!$F$6:$F$94="2021"))=0,SUMPRODUCT(--('Repartition stock'!$A$6:$A$94="2026Q2"),--('Repartition stock'!$B$6:$B$94="IT"),--('Repartition stock'!$E$6:$E$94="Millésime"),--('Repartition stock'!$F$6:$F$94="2021"),--('Repartition stock'!$J$6:$J$94="n.d."))>0),"n.d.",SUMPRODUCT(--('Repartition stock'!$A$6:$A$94="2026Q2"),--('Repartition stock'!$B$6:$B$94="IT"),--('Repartition stock'!$E$6:$E$94="Millésime"),--('Repartition stock'!$F$6:$F$94="2021"),'Repartition stock'!$J$6:$J$94)) -> n.d. | AC18: =IF(OR(COUNT(X18,X24)<>2,X24=0),"n.d.",X18/X24) -> n.d. | AE18: =IF(OR(COUNT(Z18,Z24)<>2,Z24=0),"n.d.",Z18/Z24) -> n.d.
U19: 2022 | X19: =IF(OR(SUMPRODUCT(--('Repartition stock'!$A$6:$A$94="2026Q2"),--('Repartition stock'!$B$6:$B$94="IT"),--('Repartition stock'!$E$6:$E$94="Millésime"),--('Repartition stock'!$F$6:$F$94="2022"))=0,SUMPRODUCT(--('Repartition stock'!$A$6:$A$94="2026Q2"),--('Repartition stock'!$B$6:$B$94="IT"),--('Repartition stock'!$E$6:$E$94="Millésime"),--('Repartition stock'!$F$6:$F$94="2022"),--('Repartition stock'!$G$6:$G$94="n.d."))>0),"n.d.",SUMPRODUCT(--('Repartition stock'!$A$6:$A$94="2026Q2"),--('Repartition stock'!$B$6:$B$94="IT"),--('Repartition stock'!$E$6:$E$94="Millésime"),--('Repartition stock'!$F$6:$F$94="2022"),'Repartition stock'!$G$6:$G$94)) -> n.d. | Z19: =IF(OR(SUMPRODUCT(--('Repartition stock'!$A$6:$A$94="2026Q2"),--('Repartition stock'!$B$6:$B$94="IT"),--('Repartition stock'!$E$6:$E$94="Millésime"),--('Repartition stock'!$F$6:$F$94="2022"))=0,SUMPRODUCT(--('Repartition stock'!$A$6:$A$94="2026Q2"),--('Repartition stock'!$B$6:$B$94="IT"),--('Repartition stock'!$E$6:$E$94="Millésime"),--('Repartition stock'!$F$6:$F$94="2022"),--('Repartition stock'!$J$6:$J$94="n.d."))>0),"n.d.",SUMPRODUCT(--('Repartition stock'!$A$6:$A$94="2026Q2"),--('Repartition stock'!$B$6:$B$94="IT"),--('Repartition stock'!$E$6:$E$94="Millésime"),--('Repartition stock'!$F$6:$F$94="2022"),'Repartition stock'!$J$6:$J$94)) -> n.d. | AC19: =IF(OR(COUNT(X19,X24)<>2,X24=0),"n.d.",X19/X24) -> n.d. | AE19: =IF(OR(COUNT(Z19,Z24)<>2,Z24=0),"n.d.",Z19/Z24) -> n.d.
