Workbook
Name Periodes: 'Taux'!$H$6:$H$8

Sheet Global
B1: 2026Q3 — 14 / 14 countries — Romania stock: 0 — comparison at Q3 FX
B2: GLOBAL countries: Stock analysis
B5: Q2 and Q3 translated at Q3 2026 closing FX. All 14 countries included; Romania closing stock confirmed at zero.
B8: Countries | H8: 2026Q2 at Q3 FX | K8: 2026Q3 | N8: Evolution current / prior
B11: Spain | H11: =IF(ISNUMBER('GraphData'!B7),'GraphData'!B7,"n.d.") -> 1787812 | K11: =IF(ISNUMBER('GraphData'!C7),'GraphData'!C7,"n.d.") -> 1793165 | N11: =IF(ISNUMBER('GraphData'!D7),'GraphData'!D7,"n.d.") -> 0.0029941627
B12: Germany + Austria | H12: =IF(ISNUMBER('GraphData'!B8),'GraphData'!B8,"n.d.") -> 3485465.3 | K12: =IF(ISNUMBER('GraphData'!C8),'GraphData'!C8,"n.d.") -> 2793036 | N12: =IF(ISNUMBER('GraphData'!D8),'GraphData'!D8,"n.d.") -> -0.19866194
B13: Belgium | H13: =IF(ISNUMBER('GraphData'!B9),'GraphData'!B9,"n.d.") -> 136664 | K13: =IF(ISNUMBER('GraphData'!C9),'GraphData'!C9,"n.d.") -> 147601 | N13: =IF(ISNUMBER('GraphData'!D9),'GraphData'!D9,"n.d.") -> 0.080028391
B14: Italy | H14: =IF(ISNUMBER('GraphData'!B10),'GraphData'!B10,"n.d.") -> 3023244 | K14: =IF(ISNUMBER('GraphData'!C10),'GraphData'!C10,"n.d.") -> 3434403 | N14: =IF(ISNUMBER('GraphData'!D10),'GraphData'!D10,"n.d.") -> 0.13599928
B15: Portugal | H15: =IF(ISNUMBER('GraphData'!B11),'GraphData'!B11,"n.d.") -> 593413 | K15: =IF(ISNUMBER('GraphData'!C11),'GraphData'!C11,"n.d.") -> 607594 | N15: =IF(ISNUMBER('GraphData'!D11),'GraphData'!D11,"n.d.") -> 0.023897353
B16: France | H16: =IF(ISNUMBER('GraphData'!B12),'GraphData'!B12,"n.d.") -> 3317587 | K16: =IF(ISNUMBER('GraphData'!C12),'GraphData'!C12,"n.d.") -> 2883642 | N16: =IF(ISNUMBER('GraphData'!D12),'GraphData'!D12,"n.d.") -> -0.13080139
B17: UK | H17: =IF(ISNUMBER('GraphData'!B13),'GraphData'!B13,"n.d.") -> 2860611.3 | K17: =IF(ISNUMBER('GraphData'!C13),'GraphData'!C13,"n.d.") -> 3483914.1 | N17: =IF(ISNUMBER('GraphData'!D13),'GraphData'!D13,"n.d.") -> 0.21789148
B18: South Africa | H18: =IF(ISNUMBER('GraphData'!B14),'GraphData'!B14,"n.d.") -> 1918750.9 | K18: =IF(ISNUMBER('GraphData'!C14),'GraphData'!C14,"n.d.") -> 2048298.6 | N18: =IF(ISNUMBER('GraphData'!D14),'GraphData'!D14,"n.d.") -> 0.067516661
B19: Romania | H19: =IF(ISNUMBER('GraphData'!B15),'GraphData'!B15,"n.d.") -> 48887.519 | K19: =IF(ISNUMBER('GraphData'!C15),'GraphData'!C15,"n.d.") -> 0 | N19: =IF(ISNUMBER('GraphData'!D15),'GraphData'!D15,"n.d.") -> -1
B20: Brazil | H20: =IF(ISNUMBER('GraphData'!B16),'GraphData'!B16,"n.d.") -> 3814713.5 | K20: =IF(ISNUMBER('GraphData'!C16),'GraphData'!C16,"n.d.") -> 3775169.6 | N20: =IF(ISNUMBER('GraphData'!D16),'GraphData'!D16,"n.d.") -> -0.010366149
B21: Denmark | H21: =IF(ISNUMBER('GraphData'!B17),'GraphData'!B17,"n.d.") -> 24384.545 | K21: =IF(ISNUMBER('GraphData'!C17),'GraphData'!C17,"n.d.") -> 2162.4937 | N21: =IF(ISNUMBER('GraphData'!D17),'GraphData'!D17,"n.d.") -> -0.91131704
B22: Norway | H22: =IF(ISNUMBER('GraphData'!B18),'GraphData'!B18,"n.d.") -> 11211.459 | K22: =IF(ISNUMBER('GraphData'!C18),'GraphData'!C18,"n.d.") -> 2025.348 | N22: =IF(ISNUMBER('GraphData'!D18),'GraphData'!D18,"n.d.") -> -0.81935018
B23: Sweden | H23: =IF(ISNUMBER('GraphData'!B19),'GraphData'!B19,"n.d.") -> 13809.271 | K23: =IF(ISNUMBER('GraphData'!C19),'GraphData'!C19,"n.d.") -> 15218.246 | N23: =IF(ISNUMBER('GraphData'!D19),'GraphData'!D19,"n.d.") -> 0.10203106
B24: TOTAL available perimeter | H24: =IF(COUNT(H11:H23)=13,SUM(H11:H23),"n.d.") -> 21036554 | K24: =IF(COUNT(K11:K23)=13,SUM(K11:K23),"n.d.") -> 20986229 | N24: =IF(OR(COUNT(H24,K24)<>2,H24=0),"n.d.",K24/H24-1) -> -0.0023922365
B27: Identified stock = pending + unreachable balances; Belgium adds public authority refunds.
B29: Q2 and Q3 use Q3 closing FX. Stock breakdowns retain each country’s reporting scope.
B42: Positive Balance 2026Q3 Updated country inputs and closing FX Internal
B46: GLOBAL countries: Monthly inflow and treatment efficiency
B49: EUR amounts. M-5 efficiency uses the oldest cohort in each reporting snapshot. Monthly flow view covers 13 countries. Romania monthly flows were not provided. Q2 / Q3 comparisons use Q3 FX.
O52: Monthly flow in EUR | T52: Monthly average | V52: Apr-26 | X52: May-26 | Z52: Jun-26 | AB52: Jul-26 | AD52: Aug-26 | AF52: Sep-26
O55: Total available | T55: =IF(COUNT(T56,T57,T58,T59,T60,T61,T62,T63,T64,T65,T66,T67)=12,SUM(T56,T57,T58,T59,T60,T61,T62,T63,T64,T65,T66,T67),"n.d.") -> 9829247.6 | V55: =IF(COUNT('GraphData'!B25,'GraphData'!C25,'GraphData'!D25,'GraphData'!E25,'GraphData'!F25,'GraphData'!G25,'GraphData'!H25,'GraphData'!I25,'GraphData'!J25,'GraphData'!K25,'GraphData'!L25,'GraphData'!M25)=12,SUM('GraphData'!B25,'GraphData'!C25,'GraphData'!D25,'GraphData'!E25,'GraphData'!F25,'GraphData'!G25,'GraphData'!H25,'GraphData'!I25,'GraphData'!J25,'GraphData'!K25,'GraphData'!L25,'GraphData'!M25),"n.d.") -> 11804479 | X55: =IF(COUNT('GraphData'!B26,'GraphData'!C26,'GraphData'!D26,'GraphData'!E26,'GraphData'!F26,'GraphData'!G26,'GraphData'!H26,'GraphData'!I26,'GraphData'!J26,'GraphData'!K26,'GraphData'!L26,'GraphData'!M26)=12,SUM('GraphData'!B26,'GraphData'!C26,'GraphData'!D26,'GraphData'!E26,'GraphData'!F26,'GraphData'!G26,'GraphData'!H26,'GraphData'!I26,'GraphData'!J26,'GraphData'!K26,'GraphData'!L26,'GraphData'!M26),"n.d.") -> 10798116 | Z55: =IF(COUNT('GraphData'!B27,'GraphData'!C27,'GraphData'!D27,'GraphData'!E27,'GraphData'!F27,'GraphData'!G27,'GraphData'!H27,'GraphData'!I27,'GraphData'!J27,'GraphData'!K27,'GraphData'!L27,'GraphData'!M27)=12,SUM('GraphData'!B27,'GraphData'!C27,'GraphData'!D27,'GraphData'!E27,'GraphData'!F27,'GraphData'!G27,'GraphData'!H27,'GraphData'!I27,'GraphData'!J27,'GraphData'!K27,'GraphData'!L27,'GraphData'!M27),"n.d.") -> 10593314 | AB55: =IF(COUNT('GraphData'!B28,'GraphData'!C28,'GraphData'!D28,'GraphData'!E28,'GraphData'!F28,'GraphData'!G28,'GraphData'!H28,'GraphData'!I28,'GraphData'!J28,'GraphData'!K28,'GraphData'!L28,'GraphData'!M28)=12,SUM('GraphData'!B28,'GraphData'!C28,'GraphData'!D28,'GraphData'!E28,'GraphData'!F28,'GraphData'!G28,'GraphData'!H28,'GraphData'!I28,'GraphData'!J28,'GraphData'!K28,'GraphData'!L28,'GraphData'!M28),"n.d.") -> 9884156.9 | AD55: =IF(COUNT('GraphData'!B29,'GraphData'!C29,'GraphData'!D29,'GraphData'!E29,'GraphData'!F29,'GraphData'!G29,'GraphData'!H29,'GraphData'!I29,'GraphData'!J29,'GraphData'!K29,'GraphData'!L29,'GraphData'!M29)=12,SUM('GraphData'!B29,'GraphData'!C29,'GraphData'!D29,'GraphData'!E29,'GraphData'!F29,'GraphData'!G29,'GraphData'!H29,'GraphData'!I29,'GraphData'!J29,'GraphData'!K29,'GraphData'!L29,'GraphData'!M29),"n.d.") -> 7472083.2 | AF55: =IF(COUNT('GraphData'!B30,'GraphData'!C30,'GraphData'!D30,'GraphData'!E30,'GraphData'!F30,'GraphData'!G30,'GraphData'!H30,'GraphData'!I30,'GraphData'!J30,'GraphData'!K30,'GraphData'!L30,'GraphData'!M30)=12,SUM('GraphData'!B30,'GraphData'!C30,'GraphData'!D30,'GraphData'!E30,'GraphData'!F30,'GraphData'!G30,'GraphData'!H30,'GraphData'!I30,'GraphData'!J30,'GraphData'!K30,'GraphData'!L30,'GraphData'!M30),"n.d.") -> 8423336.9
O56: Spain | T56: =IF(OR(COUNTIFS('Consolidation'!$A$6:$A$47,"2026Q3",'Consolidation'!$B$6:$B$47,"ES")<>1,COUNTIFS('Consolidation'!$A$6:$A$47,"2026Q3",'Consolidation'!$B$6:$B$47,"ES",'Consolidation'!$W$6:$W$47,"n.d.")>0),"n.d.",SUMIFS('Consolidation'!$W$6:$W$47,'Consolidation'!$A$6:$A$47,"2026Q3",'Consolidation'!$B$6:$B$47,"ES")) -> 3416903.3 | V56: =IF(ISNUMBER('GraphData'!B25),'GraphData'!B25,"n.d.") -> 3475518 | X56: =IF(ISNUMBER('GraphData'!B26),'GraphData'!B26,"n.d.") -> 3162844 | Z56: =IF(ISNUMBER('GraphData'!B27),'GraphData'!B27,"n.d.") -> 4107101 | AB56: =IF(ISNUMBER('GraphData'!B28),'GraphData'!B28,"n.d.") -> 3892550 | AD56: =IF(ISNUMBER('GraphData'!B29),'GraphData'!B29,"n.d.") -> 2506521 | AF56: =IF(ISNUMBER('GraphData'!B30),'GraphData'!B30,"n.d.") -> 3356886
O57: Germany + Austria | T57: =IF(COUNT(IF(OR(COUNTIFS('Consolidation'!$A$6:$A$47,"2026Q3",'Consolidation'!$B$6:$B$47,"DE")<>1,COUNTIFS('Consolidation'!$A$6:$A$47,"2026Q3",'Consolidation'!$B$6:$B$47,"DE",'Consolidation'!$W$6:$W$47,"n.d.")>0),"n.d.",SUMIFS('Consolidation'!$W$6:$W$47,'Consolidation'!$A$6:$A$47,"2026Q3",'Consolidation'!$B$6:$B$47,"DE")),IF(OR(COUNTIFS('Consolidation'!$A$6:$A$47,"2026Q3",'Consolidation'!$B$6:$B$47,"AT")<>1,COUNTIFS('Consolidation'!$A$6:$A$47,"2026Q3",'Consolidation'!$B$6:$B$47,"AT",'Consolidation'!$W$6:$W$47,"n.d.")>0),"n.d.",SUMIFS('Consolidation'!$W$6:$W$47,'Consolidation'!$A$6:$A$47,"2026Q3",'Consolidation'!$B$6:$B$47,"AT")))=2,SUM(IF(OR(COUNTIFS('Consolidation'!$A$6:$A$47,"2026Q3",'Consolidation'!$B$6:$B$47,"DE")<>1,COUNTIFS('Consolidation'!$A$6:$A$47,"2026Q3",'Consolidation'!$B$6:$B$47,"DE",'Consolidation'!$W$6:$W$47,"n.d.")>0),"n.d.",SUMIFS('Consolidation'!$W$6:$W$47,'Consolidation'!$A$6:$A$47,"2026Q3",'Consolidation'!$B$6:$B$47,"DE")),IF(OR(COUNTIFS('Consolidation'!$A$6:$A$47,"2026Q3",'Consolidation'!$B$6:$B$47,"AT")<>1,COUNTIFS('Consolidation'!$A$6:$A$47,"2026Q3",'Consolidation'!$B$6:$B$47,"AT",'Consolidation'!$W$6:$W$47,"n.d.")>0),"n.d.",SUMIFS('Consolidation'!$W$6:$W$47,'Consolidation'!$A$6:$A$47,"2026Q3",'Consolidation'!$B$6:$B$47,"AT"))),"n.d.") -> 843920 | V57: =IF(ISNUMBER('GraphData'!C25),'GraphData'!C25,"n.d.") -> 781466 | X57: =IF(ISNUMBER('GraphData'!C26),'GraphData'!C26,"n.d.") -> 689718 | Z57: =IF(ISNUMBER('GraphData'!C27),'GraphData'!C27,"n.d.") -> 808135 | AB57: =IF(ISNUMBER('GraphData'!C28),'GraphData'!C28,"n.d.") -> 954954 | AD57: =IF(ISNUMBER('GraphData'!C29),'GraphData'!C29,"n.d.") -> 977254 | AF57: =IF(ISNUMBER('GraphData'!C30),'GraphData'!C30,"n.d.") -> 851993
O58: Belgium | T58: =IF(OR(COUNTIFS('Consolidation'!$A$6:$A$47,"2026Q3",'Consolidation'!$B$6:$B$47,"BE")<>1,COUNTIFS('Consolidation'!$A$6:$A$47,"2026Q3",'Consolidation'!$B$6:$B$47,"BE",'Consolidation'!$W$6:$W$47,"n.d.")>0),"n.d.",SUMIFS('Consolidation'!$W$6:$W$47,'Consolidation'!$A$6:$A$47,"2026Q3",'Consolidation'!$B$6:$B$47,"BE")) -> 86982.167 | V58: =IF(ISNUMBER('GraphData'!D25),'GraphData'!D25,"n.d.") -> 105005 | X58: =IF(ISNUMBER('GraphData'!D26),'GraphData'!D26,"n.d.") -> 68164 | Z58: =IF(ISNUMBER('GraphData'!D27),'GraphData'!D27,"n.d.") -> 104341 | AB58: =IF(ISNUMBER('GraphData'!D28),'GraphData'!D28,"n.d.") -> 71809 | AD58: =IF(ISNUMBER('GraphData'!D29),'GraphData'!D29,"n.d.") -> 119870 | AF58: =IF(ISNUMBER('GraphData'!D30),'GraphData'!D30,"n.d.") -> 52704
O59: Italy | T59: =IF(OR(COUNTIFS('Consolidation'!$A$6:$A$47,"2026Q3",'Consolidation'!$B$6:$B$47,"IT")<>1,COUNTIFS('Consolidation'!$A$6:$A$47,"2026Q3",'Consolidation'!$B$6:$B$47,"IT",'Consolidation'!$W$6:$W$47,"n.d.")>0),"n.d.",SUMIFS('Consolidation'!$W$6:$W$47,'Consolidation'!$A$6:$A$47,"2026Q3",'Consolidation'!$B$6:$B$47,"IT")) -> 1092477.8 | V59: =IF(ISNUMBER('GraphData'!E25),'GraphData'!E25,"n.d.") -> 1199204 | X59: =IF(ISNUMBER('GraphData'!E26),'GraphData'!E26,"n.d.") -> 1425617 | Z59: =IF(ISNUMBER('GraphData'!E27),'GraphData'!E27,"n.d.") -> 977488 | AB59: =IF(ISNUMBER('GraphData'!E28),'GraphData'!E28,"n.d.") -> 1234017 | AD59: =IF(ISNUMBER('GraphData'!E29),'GraphData'!E29,"n.d.") -> 898183 | AF59: =IF(ISNUMBER('GraphData'!E30),'GraphData'!E30,"n.d.") -> 820358
O60: Portugal | T60: =IF(OR(COUNTIFS('Consolidation'!$A$6:$A$47,"2026Q3",'Consolidation'!$B$6:$B$47,"PT")<>1,COUNTIFS('Consolidation'!$A$6:$A$47,"2026Q3",'Consolidation'!$B$6:$B$47,"PT",'Consolidation'!$W$6:$W$47,"n.d.")>0),"n.d.",SUMIFS('Consolidation'!$W$6:$W$47,'Consolidation'!$A$6:$A$47,"2026Q3",'Consolidation'!$B$6:$B$47,"PT")) -> 2355231.7 | V60: =IF(ISNUMBER('GraphData'!F25),'GraphData'!F25,"n.d.") -> 4060466 | X60: =IF(ISNUMBER('GraphData'!F26),'GraphData'!F26,"n.d.") -> 3650675 | Z60: =IF(ISNUMBER('GraphData'!F27),'GraphData'!F27,"n.d.") -> 2534318 | AB60: =IF(ISNUMBER('GraphData'!F28),'GraphData'!F28,"n.d.") -> 1649935 | AD60: =IF(ISNUMBER('GraphData'!F29),'GraphData'!F29,"n.d.") -> 1234586 | AF60: =IF(ISNUMBER('GraphData'!F30),'GraphData'!F30,"n.d.") -> 1001410
O61: France | T61: =IF(OR(COUNTIFS('Consolidation'!$A$6:$A$47,"2026Q3",'Consolidation'!$B$6:$B$47,"FR")<>1,COUNTIFS('Consolidation'!$A$6:$A$47,"2026Q3",'Consolidation'!$B$6:$B$47,"FR",'Consolidation'!$W$6:$W$47,"n.d.")>0),"n.d.",SUMIFS('Consolidation'!$W$6:$W$47,'Consolidation'!$A$6:$A$47,"2026Q3",'Consolidation'!$B$6:$B$47,"FR")) -> 1574089.2 | V61: =IF(ISNUMBER('GraphData'!G25),'GraphData'!G25,"n.d.") -> 1825315 | X61: =IF(ISNUMBER('GraphData'!G26),'GraphData'!G26,"n.d.") -> 1394486 | Z61: =IF(ISNUMBER('GraphData'!G27),'GraphData'!G27,"n.d.") -> 1738908 | AB61: =IF(ISNUMBER('GraphData'!G28),'GraphData'!G28,"n.d.") -> 1680101 | AD61: =IF(ISNUMBER('GraphData'!G29),'GraphData'!G29,"n.d.") -> 1332248 | AF61: =IF(ISNUMBER('GraphData'!G30),'GraphData'!G30,"n.d.") -> 1473477
O62: UK | T62: =IF(OR(COUNTIFS('Consolidation'!$A$6:$A$47,"2026Q3",'Consolidation'!$B$6:$B$47,"UK")<>1,COUNTIFS('Consolidation'!$A$6:$A$47,"2026Q3",'Consolidation'!$B$6:$B$47,"UK",'Consolidation'!$W$6:$W$47,"n.d.")>0),"n.d.",SUMIFS('Consolidation'!$W$6:$W$47,'Consolidation'!$A$6:$A$47,"2026Q3",'Consolidation'!$B$6:$B$47,"UK")) -> 211307.18 | V62: =IF(ISNUMBER('GraphData'!H25),'GraphData'!H25,"n.d.") -> 120964.31 | X62: =IF(ISNUMBER('GraphData'!H26),'GraphData'!H26,"n.d.") -> 170612.4 | Z62: =IF(ISNUMBER('GraphData'!H27),'GraphData'!H27,"n.d.") -> 93546.158 | AB62: =IF(ISNUMBER('GraphData'!H28),'GraphData'!H28,"n.d.") -> 134405.96 | AD62: =IF(ISNUMBER('GraphData'!H29),'GraphData'!H29,"n.d.") -> 157081.8 | AF62: =IF(ISNUMBER('GraphData'!H30),'GraphData'!H30,"n.d.") -> 591232.46
O63: South Africa | T63: =IF(OR(COUNTIFS('Consolidation'!$A$6:$A$47,"2026Q3",'Consolidation'!$B$6:$B$47,"ZA")<>1,COUNTIFS('Consolidation'!$A$6:$A$47,"2026Q3",'Consolidation'!$B$6:$B$47,"ZA",'Consolidation'!$W$6:$W$47,"n.d.")>0),"n.d.",SUMIFS('Consolidation'!$W$6:$W$47,'Consolidation'!$A$6:$A$47,"2026Q3",'Consolidation'!$B$6:$B$47,"ZA")) -> 206027.81 | V63: =IF(ISNUMBER('GraphData'!I25),'GraphData'!I25,"n.d.") -> 178090.78 | X63: =IF(ISNUMBER('GraphData'!I26),'GraphData'!I26,"n.d.") -> 185044.79 | Z63: =IF(ISNUMBER('GraphData'!I27),'GraphData'!I27,"n.d.") -> 190318.61 | AB63: =IF(ISNUMBER('GraphData'!I28),'GraphData'!I28,"n.d.") -> 228755.46 | AD63: =IF(ISNUMBER('GraphData'!I29),'GraphData'!I29,"n.d.") -> 220324.51 | AF63: =IF(ISNUMBER('GraphData'!I30),'GraphData'!I30,"n.d.") -> 233632.74
O64: Brazil | T64: =IF(OR(COUNTIFS('Consolidation'!$A$6:$A$47,"2026Q3",'Consolidation'!$B$6:$B$47,"BR")<>1,COUNTIFS('Consolidation'!$A$6:$A$47,"2026Q3",'Consolidation'!$B$6:$B$47,"BR",'Consolidation'!$W$6:$W$47,"n.d.")>0),"n.d.",SUMIFS('Consolidation'!$W$6:$W$47,'Consolidation'!$A$6:$A$47,"2026Q3",'Consolidation'!$B$6:$B$47,"BR")) -> 2094.2987 | V64: =IF(ISNUMBER('GraphData'!J25),'GraphData'!J25,"n.d.") -> 3875.6449 | X64: =IF(ISNUMBER('GraphData'!J26),'GraphData'!J26,"n.d.") -> 2540.0568 | Z64: =IF(ISNUMBER('GraphData'!J27),'GraphData'!J27,"n.d.") -> 1589.9813 | AB64: =IF(ISNUMBER('GraphData'!J28),'GraphData'!J28,"n.d.") -> 1700.7757 | AD64: =IF(ISNUMBER('GraphData'!J29),'GraphData'!J29,"n.d.") -> 250.32392 | AF64: =IF(ISNUMBER('GraphData'!J30),'GraphData'!J30,"n.d.") -> 2609.0096
O65: Denmark | T65: =IF(OR(COUNTIFS('Consolidation'!$A$6:$A$47,"2026Q3",'Consolidation'!$B$6:$B$47,"DK")<>1,COUNTIFS('Consolidation'!$A$6:$A$47,"2026Q3",'Consolidation'!$B$6:$B$47,"DK",'Consolidation'!$W$6:$W$47,"n.d.")>0),"n.d.",SUMIFS('Consolidation'!$W$6:$W$47,'Consolidation'!$A$6:$A$47,"2026Q3",'Consolidation'!$B$6:$B$47,"DK")) -> 12951.736 | V65: =IF(ISNUMBER('GraphData'!K25),'GraphData'!K25,"n.d.") -> 15033.975 | X65: =IF(ISNUMBER('GraphData'!K26),'GraphData'!K26,"n.d.") -> 22642.802 | Z65: =IF(ISNUMBER('GraphData'!K27),'GraphData'!K27,"n.d.") -> 11921.132 | AB65: =IF(ISNUMBER('GraphData'!K28),'GraphData'!K28,"n.d.") -> 9958.9094 | AD65: =IF(ISNUMBER('GraphData'!K29),'GraphData'!K29,"n.d.") -> 10757.907 | AF65: =IF(ISNUMBER('GraphData'!K30),'GraphData'!K30,"n.d.") -> 7395.6925
O66: Norway | T66: =IF(OR(COUNTIFS('Consolidation'!$A$6:$A$47,"2026Q3",'Consolidation'!$B$6:$B$47,"NO")<>1,COUNTIFS('Consolidation'!$A$6:$A$47,"2026Q3",'Consolidation'!$B$6:$B$47,"NO",'Consolidation'!$W$6:$W$47,"n.d.")>0),"n.d.",SUMIFS('Consolidation'!$W$6:$W$47,'Consolidation'!$A$6:$A$47,"2026Q3",'Consolidation'!$B$6:$B$47,"NO")) -> 6054.5251 | V66: =IF(ISNUMBER('GraphData'!L25),'GraphData'!L25,"n.d.") -> 5652.2177 | X66: =IF(ISNUMBER('GraphData'!L26),'GraphData'!L26,"n.d.") -> 13480.901 | Z66: =IF(ISNUMBER('GraphData'!L27),'GraphData'!L27,"n.d.") -> 5095.5152 | AB66: =IF(ISNUMBER('GraphData'!L28),'GraphData'!L28,"n.d.") -> 3901.6093 | AD66: =IF(ISNUMBER('GraphData'!L29),'GraphData'!L29,"n.d.") -> 3950.3792 | AF66: =IF(ISNUMBER('GraphData'!L30),'GraphData'!L30,"n.d.") -> 4246.5288
O67: Sweden | T67: =IF(OR(COUNTIFS('Consolidation'!$A$6:$A$47,"2026Q3",'Consolidation'!$B$6:$B$47,"SE")<>1,COUNTIFS('Consolidation'!$A$6:$A$47,"2026Q3",'Consolidation'!$B$6:$B$47,"SE",'Consolidation'!$W$6:$W$47,"n.d.")>0),"n.d.",SUMIFS('Consolidation'!$W$6:$W$47,'Consolidation'!$A$6:$A$47,"2026Q3",'Consolidation'!$B$6:$B$47,"SE")) -> 21207.907 | V67: =IF(ISNUMBER('GraphData'!M25),'GraphData'!M25,"n.d.") -> 33888.154 | X67: =IF(ISNUMBER('GraphData'!M26),'GraphData'!M26,"n.d.") -> 12290.64 | Z67: =IF(ISNUMBER('GraphData'!M27),'GraphData'!M27,"n.d.") -> 20551.693 | AB67: =IF(ISNUMBER('GraphData'!M28),'GraphData'!M28,"n.d.") -> 22068.183 | AD67: =IF(ISNUMBER('GraphData'!M29),'GraphData'!M29,"n.d.") -> 11056.328 | AF67: =IF(ISNUMBER('GraphData'!M30),'GraphData'!M30,"n.d.") -> 27392.445
O70: Country | T70: Efficiency in amount | Z70: Efficiency in number
T71: 2026Q2 | W71: 2026Q3 | Z71: 2026Q2 | AC71: 2026Q3
O73: Spain | T73: ='GraphData'!D36 -> 0.99316426 | W73: ='GraphData'!E36 -> 0.98598079 | Z73: ='GraphData'!B36 -> 0.98940544 | AC73: ='GraphData'!C36 -> 0.95393075
...

Sheet CORE Stock
B2: CORE countries: Stock analysis
B5: Q2 and Q3 translated at Q3 2026 closing FX. Germany and Austria combined in consolidated rows.
B8: Countries | H8: 2026Q2 at Q3 FX | K8: 2026Q3 | N8: Evolution current / prior
B11: Spain | H11: =IF(ISNUMBER('GraphData'!B53),'GraphData'!B53,"n.d.") -> 1787812 | K11: =IF(ISNUMBER('GraphData'!C53),'GraphData'!C53,"n.d.") -> 1793165 | N11: =IF(ISNUMBER('GraphData'!D53),'GraphData'!D53,"n.d.") -> 0.0029941627
B12: Germany + Austria | H12: =IF(ISNUMBER('GraphData'!B54),'GraphData'!B54,"n.d.") -> 3485465.3 | K12: =IF(ISNUMBER('GraphData'!C54),'GraphData'!C54,"n.d.") -> 2793036 | N12: =IF(ISNUMBER('GraphData'!D54),'GraphData'!D54,"n.d.") -> -0.19866194
B13: Belgium | H13: =IF(ISNUMBER('GraphData'!B55),'GraphData'!B55,"n.d.") -> 136664 | K13: =IF(ISNUMBER('GraphData'!C55),'GraphData'!C55,"n.d.") -> 147601 | N13: =IF(ISNUMBER('GraphData'!D55),'GraphData'!D55,"n.d.") -> 0.080028391
B14: Italy | H14: =IF(ISNUMBER('GraphData'!B56),'GraphData'!B56,"n.d.") -> 3023244 | K14: =IF(ISNUMBER('GraphData'!C56),'GraphData'!C56,"n.d.") -> 3434403 | N14: =IF(ISNUMBER('GraphData'!D56),'GraphData'!D56,"n.d.") -> 0.13599928
B15: Portugal | H15: =IF(ISNUMBER('GraphData'!B57),'GraphData'!B57,"n.d.") -> 593413 | K15: =IF(ISNUMBER('GraphData'!C57),'GraphData'!C57,"n.d.") -> 607594 | N15: =IF(ISNUMBER('GraphData'!D57),'GraphData'!D57,"n.d.") -> 0.023897353
B16: France | H16: =IF(ISNUMBER('GraphData'!B58),'GraphData'!B58,"n.d.") -> 3317587 | K16: =IF(ISNUMBER('GraphData'!C58),'GraphData'!C58,"n.d.") -> 2883642 | N16: =IF(ISNUMBER('GraphData'!D58),'GraphData'!D58,"n.d.") -> -0.13080139
B17: UK | H17: =IF(ISNUMBER('GraphData'!B59),'GraphData'!B59,"n.d.") -> 2860611.3 | K17: =IF(ISNUMBER('GraphData'!C59),'GraphData'!C59,"n.d.") -> 3483914.1 | N17: =IF(ISNUMBER('GraphData'!D59),'GraphData'!D59,"n.d.") -> 0.21789148
B18: South Africa | H18: =IF(ISNUMBER('GraphData'!B60),'GraphData'!B60,"n.d.") -> 1918750.9 | K18: =IF(ISNUMBER('GraphData'!C60),'GraphData'!C60,"n.d.") -> 2048298.6 | N18: =IF(ISNUMBER('GraphData'!D60),'GraphData'!D60,"n.d.") -> 0.067516661
B19: TOTAL available perimeter | H19: =IF(COUNT(H11:H18)=8,SUM(H11:H18),"n.d.") -> 17123548 | K19: =IF(COUNT(K11:K18)=8,SUM(K11:K18),"n.d.") -> 17191654 | N19: =IF(OR(COUNT(H19,K19)<>2,H19=0),"n.d.",K19/H19-1) -> 0.0039773406
B24: Identified stock = pending + unreachable balances; Belgium adds public authority refunds.
B26: Q2 and Q3 use Q3 closing FX. Stock breakdowns retain each country’s reporting scope.
B42: Positive Balance 2026Q3 Updated country inputs and closing FX Internal

Sheet CORE Flows
B2: CORE countries: Monthly inflow and treatment efficiency
B5: EUR amounts. M-5 efficiency uses the oldest cohort in each reporting snapshot. Q2 and Q3 translated at Q3 2026 closing FX. Germany and Austria combined in consolidated rows.
O8: Monthly flow in EUR | T8: Monthly average | V8: Apr-26 | X8: May-26 | Z8: Jun-26 | AB8: Jul-26 | AD8: Aug-26 | AF8: Sep-26
O11: Total available | T11: =IF(COUNT(T12,T13,T14,T15,T16,T17,T18,T19)=8,SUM(T12,T13,T14,T15,T16,T17,T18,T19),"n.d.") -> 9786939.2 | V11: =IF(COUNT('GraphData'!B66,'GraphData'!C66,'GraphData'!D66,'GraphData'!E66,'GraphData'!F66,'GraphData'!G66,'GraphData'!H66,'GraphData'!I66)=8,SUM('GraphData'!B66,'GraphData'!C66,'GraphData'!D66,'GraphData'!E66,'GraphData'!F66,'GraphData'!G66,'GraphData'!H66,'GraphData'!I66),"n.d.") -> 11746029 | X11: =IF(COUNT('GraphData'!B67,'GraphData'!C67,'GraphData'!D67,'GraphData'!E67,'GraphData'!F67,'GraphData'!G67,'GraphData'!H67,'GraphData'!I67)=8,SUM('GraphData'!B67,'GraphData'!C67,'GraphData'!D67,'GraphData'!E67,'GraphData'!F67,'GraphData'!G67,'GraphData'!H67,'GraphData'!I67),"n.d.") -> 10747161 | Z11: =IF(COUNT('GraphData'!B68,'GraphData'!C68,'GraphData'!D68,'GraphData'!E68,'GraphData'!F68,'GraphData'!G68,'GraphData'!H68,'GraphData'!I68)=8,SUM('GraphData'!B68,'GraphData'!C68,'GraphData'!D68,'GraphData'!E68,'GraphData'!F68,'GraphData'!G68,'GraphData'!H68,'GraphData'!I68),"n.d.") -> 10554156 | AB11: =IF(COUNT('GraphData'!B69,'GraphData'!C69,'GraphData'!D69,'GraphData'!E69,'GraphData'!F69,'GraphData'!G69,'GraphData'!H69,'GraphData'!I69)=8,SUM('GraphData'!B69,'GraphData'!C69,'GraphData'!D69,'GraphData'!E69,'GraphData'!F69,'GraphData'!G69,'GraphData'!H69,'GraphData'!I69),"n.d.") -> 9846527.4 | AD11: =IF(COUNT('GraphData'!B70,'GraphData'!C70,'GraphData'!D70,'GraphData'!E70,'GraphData'!F70,'GraphData'!G70,'GraphData'!H70,'GraphData'!I70)=8,SUM('GraphData'!B70,'GraphData'!C70,'GraphData'!D70,'GraphData'!E70,'GraphData'!F70,'GraphData'!G70,'GraphData'!H70,'GraphData'!I70),"n.d.") -> 7446068.3 | AF11: =IF(COUNT('GraphData'!B71,'GraphData'!C71,'GraphData'!D71,'GraphData'!E71,'GraphData'!F71,'GraphData'!G71,'GraphData'!H71,'GraphData'!I71)=8,SUM('GraphData'!B71,'GraphData'!C71,'GraphData'!D71,'GraphData'!E71,'GraphData'!F71,'GraphData'!G71,'GraphData'!H71,'GraphData'!I71),"n.d.") -> 8381693.2
O12: Spain | T12: =IF(OR(COUNTIFS('Consolidation'!$A$6:$A$47,"2026Q3",'Consolidation'!$B$6:$B$47,"ES")<>1,COUNTIFS('Consolidation'!$A$6:$A$47,"2026Q3",'Consolidation'!$B$6:$B$47,"ES",'Consolidation'!$W$6:$W$47,"n.d.")>0),"n.d.",SUMIFS('Consolidation'!$W$6:$W$47,'Consolidation'!$A$6:$A$47,"2026Q3",'Consolidation'!$B$6:$B$47,"ES")) -> 3416903.3 | V12: =IF(ISNUMBER('GraphData'!B66),'GraphData'!B66,"n.d.") -> 3475518 | X12: =IF(ISNUMBER('GraphData'!B67),'GraphData'!B67,"n.d.") -> 3162844 | Z12: =IF(ISNUMBER('GraphData'!B68),'GraphData'!B68,"n.d.") -> 4107101 | AB12: =IF(ISNUMBER('GraphData'!B69),'GraphData'!B69,"n.d.") -> 3892550 | AD12: =IF(ISNUMBER('GraphData'!B70),'GraphData'!B70,"n.d.") -> 2506521 | AF12: =IF(ISNUMBER('GraphData'!B71),'GraphData'!B71,"n.d.") -> 3356886
O13: Germany + Austria | T13: =IF(COUNT(IF(OR(COUNTIFS('Consolidation'!$A$6:$A$47,"2026Q3",'Consolidation'!$B$6:$B$47,"DE")<>1,COUNTIFS('Consolidation'!$A$6:$A$47,"2026Q3",'Consolidation'!$B$6:$B$47,"DE",'Consolidation'!$W$6:$W$47,"n.d.")>0),"n.d.",SUMIFS('Consolidation'!$W$6:$W$47,'Consolidation'!$A$6:$A$47,"2026Q3",'Consolidation'!$B$6:$B$47,"DE")),IF(OR(COUNTIFS('Consolidation'!$A$6:$A$47,"2026Q3",'Consolidation'!$B$6:$B$47,"AT")<>1,COUNTIFS('Consolidation'!$A$6:$A$47,"2026Q3",'Consolidation'!$B$6:$B$47,"AT",'Consolidation'!$W$6:$W$47,"n.d.")>0),"n.d.",SUMIFS('Consolidation'!$W$6:$W$47,'Consolidation'!$A$6:$A$47,"2026Q3",'Consolidation'!$B$6:$B$47,"AT")))=2,SUM(IF(OR(COUNTIFS('Consolidation'!$A$6:$A$47,"2026Q3",'Consolidation'!$B$6:$B$47,"DE")<>1,COUNTIFS('Consolidation'!$A$6:$A$47,"2026Q3",'Consolidation'!$B$6:$B$47,"DE",'Consolidation'!$W$6:$W$47,"n.d.")>0),"n.d.",SUMIFS('Consolidation'!$W$6:$W$47,'Consolidation'!$A$6:$A$47,"2026Q3",'Consolidation'!$B$6:$B$47,"DE")),IF(OR(COUNTIFS('Consolidation'!$A$6:$A$47,"2026Q3",'Consolidation'!$B$6:$B$47,"AT")<>1,COUNTIFS('Consolidation'!$A$6:$A$47,"2026Q3",'Consolidation'!$B$6:$B$47,"AT",'Consolidation'!$W$6:$W$47,"n.d.")>0),"n.d.",SUMIFS('Consolidation'!$W$6:$W$47,'Consolidation'!$A$6:$A$47,"2026Q3",'Consolidation'!$B$6:$B$47,"AT"))),"n.d.") -> 843920 | V13: =IF(ISNUMBER('GraphData'!C66),'GraphData'!C66,"n.d.") -> 781466 | X13: =IF(ISNUMBER('GraphData'!C67),'GraphData'!C67,"n.d.") -> 689718 | Z13: =IF(ISNUMBER('GraphData'!C68),'GraphData'!C68,"n.d.") -> 808135 | AB13: =IF(ISNUMBER('GraphData'!C69),'GraphData'!C69,"n.d.") -> 954954 | AD13: =IF(ISNUMBER('GraphData'!C70),'GraphData'!C70,"n.d.") -> 977254 | AF13: =IF(ISNUMBER('GraphData'!C71),'GraphData'!C71,"n.d.") -> 851993
O14: Belgium | T14: =IF(OR(COUNTIFS('Consolidation'!$A$6:$A$47,"2026Q3",'Consolidation'!$B$6:$B$47,"BE")<>1,COUNTIFS('Consolidation'!$A$6:$A$47,"2026Q3",'Consolidation'!$B$6:$B$47,"BE",'Consolidation'!$W$6:$W$47,"n.d.")>0),"n.d.",SUMIFS('Consolidation'!$W$6:$W$47,'Consolidation'!$A$6:$A$47,"2026Q3",'Consolidation'!$B$6:$B$47,"BE")) -> 86982.167 | V14: =IF(ISNUMBER('GraphData'!D66),'GraphData'!D66,"n.d.") -> 105005 | X14: =IF(ISNUMBER('GraphData'!D67),'GraphData'!D67,"n.d.") -> 68164 | Z14: =IF(ISNUMBER('GraphData'!D68),'GraphData'!D68,"n.d.") -> 104341 | AB14: =IF(ISNUMBER('GraphData'!D69),'GraphData'!D69,"n.d.") -> 71809 | AD14: =IF(ISNUMBER('GraphData'!D70),'GraphData'!D70,"n.d.") -> 119870 | AF14: =IF(ISNUMBER('GraphData'!D71),'GraphData'!D71,"n.d.") -> 52704
O15: Italy | T15: =IF(OR(COUNTIFS('Consolidation'!$A$6:$A$47,"2026Q3",'Consolidation'!$B$6:$B$47,"IT")<>1,COUNTIFS('Consolidation'!$A$6:$A$47,"2026Q3",'Consolidation'!$B$6:$B$47,"IT",'Consolidation'!$W$6:$W$47,"n.d.")>0),"n.d.",SUMIFS('Consolidation'!$W$6:$W$47,'Consolidation'!$A$6:$A$47,"2026Q3",'Consolidation'!$B$6:$B$47,"IT")) -> 1092477.8 | V15: =IF(ISNUMBER('GraphData'!E66),'GraphData'!E66,"n.d.") -> 1199204 | X15: =IF(ISNUMBER('GraphData'!E67),'GraphData'!E67,"n.d.") -> 1425617 | Z15: =IF(ISNUMBER('GraphData'!E68),'GraphData'!E68,"n.d.") -> 977488 | AB15: =IF(ISNUMBER('GraphData'!E69),'GraphData'!E69,"n.d.") -> 1234017 | AD15: =IF(ISNUMBER('GraphData'!E70),'GraphData'!E70,"n.d.") -> 898183 | AF15: =IF(ISNUMBER('GraphData'!E71),'GraphData'!E71,"n.d.") -> 820358
O16: Portugal | T16: =IF(OR(COUNTIFS('Consolidation'!$A$6:$A$47,"2026Q3",'Consolidation'!$B$6:$B$47,"PT")<>1,COUNTIFS('Consolidation'!$A$6:$A$47,"2026Q3",'Consolidation'!$B$6:$B$47,"PT",'Consolidation'!$W$6:$W$47,"n.d.")>0),"n.d.",SUMIFS('Consolidation'!$W$6:$W$47,'Consolidation'!$A$6:$A$47,"2026Q3",'Consolidation'!$B$6:$B$47,"PT")) -> 2355231.7 | V16: =IF(ISNUMBER('GraphData'!F66),'GraphData'!F66,"n.d.") -> 4060466 | X16: =IF(ISNUMBER('GraphData'!F67),'GraphData'!F67,"n.d.") -> 3650675 | Z16: =IF(ISNUMBER('GraphData'!F68),'GraphData'!F68,"n.d.") -> 2534318 | AB16: =IF(ISNUMBER('GraphData'!F69),'GraphData'!F69,"n.d.") -> 1649935 | AD16: =IF(ISNUMBER('GraphData'!F70),'GraphData'!F70,"n.d.") -> 1234586 | AF16: =IF(ISNUMBER('GraphData'!F71),'GraphData'!F71,"n.d.") -> 1001410
O17: France | T17: =IF(OR(COUNTIFS('Consolidation'!$A$6:$A$47,"2026Q3",'Consolidation'!$B$6:$B$47,"FR")<>1,COUNTIFS('Consolidation'!$A$6:$A$47,"2026Q3",'Consolidation'!$B$6:$B$47,"FR",'Consolidation'!$W$6:$W$47,"n.d.")>0),"n.d.",SUMIFS('Consolidation'!$W$6:$W$47,'Consolidation'!$A$6:$A$47,"2026Q3",'Consolidation'!$B$6:$B$47,"FR")) -> 1574089.2 | V17: =IF(ISNUMBER('GraphData'!G66),'GraphData'!G66,"n.d.") -> 1825315 | X17: =IF(ISNUMBER('GraphData'!G67),'GraphData'!G67,"n.d.") -> 1394486 | Z17: =IF(ISNUMBER('GraphData'!G68),'GraphData'!G68,"n.d.") -> 1738908 | AB17: =IF(ISNUMBER('GraphData'!G69),'GraphData'!G69,"n.d.") -> 1680101 | AD17: =IF(ISNUMBER('GraphData'!G70),'GraphData'!G70,"n.d.") -> 1332248 | AF17: =IF(ISNUMBER('GraphData'!G71),'GraphData'!G71,"n.d.") -> 1473477
O18: UK | T18: =IF(OR(COUNTIFS('Consolidation'!$A$6:$A$47,"2026Q3",'Consolidation'!$B$6:$B$47,"UK")<>1,COUNTIFS('Consolidation'!$A$6:$A$47,"2026Q3",'Consolidation'!$B$6:$B$47,"UK",'Consolidation'!$W$6:$W$47,"n.d.")>0),"n.d.",SUMIFS('Consolidation'!$W$6:$W$47,'Consolidation'!$A$6:$A$47,"2026Q3",'Consolidation'!$B$6:$B$47,"UK")) -> 211307.18 | V18: =IF(ISNUMBER('GraphData'!H66),'GraphData'!H66,"n.d.") -> 120964.31 | X18: =IF(ISNUMBER('GraphData'!H67),'GraphData'!H67,"n.d.") -> 170612.4 | Z18: =IF(ISNUMBER('GraphData'!H68),'GraphData'!H68,"n.d.") -> 93546.158 | AB18: =IF(ISNUMBER('GraphData'!H69),'GraphData'!H69,"n.d.") -> 134405.96 | AD18: =IF(ISNUMBER('GraphData'!H70),'GraphData'!H70,"n.d.") -> 157081.8 | AF18: =IF(ISNUMBER('GraphData'!H71),'GraphData'!H71,"n.d.") -> 591232.46
O19: South Africa | T19: =IF(OR(COUNTIFS('Consolidation'!$A$6:$A$47,"2026Q3",'Consolidation'!$B$6:$B$47,"ZA")<>1,COUNTIFS('Consolidation'!$A$6:$A$47,"2026Q3",'Consolidation'!$B$6:$B$47,"ZA",'Consolidation'!$W$6:$W$47,"n.d.")>0),"n.d.",SUMIFS('Consolidation'!$W$6:$W$47,'Consolidation'!$A$6:$A$47,"2026Q3",'Consolidation'!$B$6:$B$47,"ZA")) -> 206027.81 | V19: =IF(ISNUMBER('GraphData'!I66),'GraphData'!I66,"n.d.") -> 178090.78 | X19: =IF(ISNUMBER('GraphData'!I67),'GraphData'!I67,"n.d.") -> 185044.79 | Z19: =IF(ISNUMBER('GraphData'!I68),'GraphData'!I68,"n.d.") -> 190318.61 | AB19: =IF(ISNUMBER('GraphData'!I69),'GraphData'!I69,"n.d.") -> 228755.46 | AD19: =IF(ISNUMBER('GraphData'!I70),'GraphData'!I70,"n.d.") -> 220324.51 | AF19: =IF(ISNUMBER('GraphData'!I71),'GraphData'!I71,"n.d.") -> 233632.74
O22: Country | T22: Efficiency in amount | Z22: Efficiency in number
T23: 2026Q2 | W23: 2026Q3 | Z23: 2026Q2 | AC23: 2026Q3
O25: Spain | T25: ='GraphData'!D77 -> 0.99316426 | W25: ='GraphData'!E77 -> 0.98598079 | Z25: ='GraphData'!B77 -> 0.98940544 | AC25: ='GraphData'!C77 -> 0.95393075
O26: Germany + Austria | T26: ='GraphData'!D78 -> 0.71045609 | W26: ='GraphData'!E78 -> 0.85377739 | Z26: ='GraphData'!B78 -> 0.60150876 | AC26: ='GraphData'!C78 -> 0.58142228
O27: Belgium | T27: ='GraphData'!D79 -> 1 | W27: ='GraphData'!E79 -> 1 | Z27: ='GraphData'!B79 -> 1 | AC27: ='GraphData'!C79 -> 1
O28: Italy | T28: ='GraphData'!D80 -> 0.98437847 | W28: ='GraphData'!E80 -> 0.97577393 | Z28: ='GraphData'!B80 -> 0.9484959 | AC28: ='GraphData'!C80 -> 0.93703938
O29: Portugal | T29: ='GraphData'!D81 -> 0.99115399 | W29: ='GraphData'!E81 -> 0.9969703 | Z29: ='GraphData'!B81 -> 0.60787772 | AC29: ='GraphData'!C81 -> 0.93985925
O30: France | T30: ='GraphData'!D82 -> 0.97773484 | W30: ='GraphData'!E82 -> 1 | Z30: ='GraphData'!B82 -> 0.94037067 | AC30: ='GraphData'!C82 -> 1
O31: UK | T31: ='GraphData'!D83 -> 0.67319991 | W31: ='GraphData'!E83 -> 0.79313247 | Z31: ='GraphData'!B83 -> 0.30129753 | AC31: ='GraphData'!C83 -> 0.69519451
O32: South Africa | T32: ='GraphData'!D84 -> 0.64934305 | W32: ='GraphData'!E84 -> 0.69269038 | Z32: ='GraphData'!B84 -> 0.85499812 | AC32: ='GraphData'!C84 -> 0.85710015
O34: Compare the same M-5 cohort maturity across reporting dates.
B42: Positive Balance 2026Q3 Updated country inputs and closing FX Internal

Sheet NON CORE Stock
B2: NON CORE countries: Stock analysis
B5: Q2 and Q3 translated at Q3 2026 closing FX. Romania closing stock confirmed at zero.
B8: Countries | H8: 2026Q2 at Q3 FX | K8: 2026Q3 | N8: Evolution current / prior | R8: Stock in EUR | W8: Total | Z8: <2025 | AB8: 2025 | AD8: 2026
B11: Romania | H11: =IF(ISNUMBER('GraphData'!B90),'GraphData'!B90,"n.d.") -> 48887.519 | K11: =IF(ISNUMBER('GraphData'!C90),'GraphData'!C90,"n.d.") -> 0 | N11: =IF(ISNUMBER('GraphData'!D90),'GraphData'!D90,"n.d.") -> -1 | R11: Romania | W11: =IF(ISNUMBER('GraphData'!C90),'GraphData'!C90,"n.d.") -> 0 | Z11: =IF(ISNUMBER('GraphData'!F90),'GraphData'!F90,"n.d.") -> 0 | AB11: =IF(ISNUMBER('GraphData'!G90),'GraphData'!G90,"n.d.") -> 0 | AD11: =IF(ISNUMBER('GraphData'!H90),'GraphData'!H90,"n.d.") -> 0
B12: Brazil | H12: =IF(ISNUMBER('GraphData'!B91),'GraphData'!B91,"n.d.") -> 3814713.5 | K12: =IF(ISNUMBER('GraphData'!C91),'GraphData'!C91,"n.d.") -> 3775169.6 | N12: =IF(ISNUMBER('GraphData'!D91),'GraphData'!D91,"n.d.") -> -0.010366149 | R12: Brazil | W12: =IF(ISNUMBER('GraphData'!C91),'GraphData'!C91,"n.d.") -> 3775169.6 | Z12: =IF(ISNUMBER('GraphData'!F91),'GraphData'!F91,"n.d.") -> 3645132.6 | AB12: =IF(ISNUMBER('GraphData'!G91),'GraphData'!G91,"n.d.") -> 112194 | AD12: =IF(ISNUMBER('GraphData'!H91),'GraphData'!H91,"n.d.") -> 17842.996
B13: Denmark | H13: =IF(ISNUMBER('GraphData'!B92),'GraphData'!B92,"n.d.") -> 24384.545 | K13: =IF(ISNUMBER('GraphData'!C92),'GraphData'!C92,"n.d.") -> 2162.4937 | N13: =IF(ISNUMBER('GraphData'!D92),'GraphData'!D92,"n.d.") -> -0.91131704 | R13: Denmark | W13: =IF(ISNUMBER('GraphData'!C92),'GraphData'!C92,"n.d.") -> 2162.4937 | Z13: =IF(ISNUMBER('GraphData'!F92),'GraphData'!F92,"n.d.") -> 0 | AB13: =IF(ISNUMBER('GraphData'!G92),'GraphData'!G92,"n.d.") -> 0 | AD13: =IF(ISNUMBER('GraphData'!H92),'GraphData'!H92,"n.d.") -> 2162.4937
B14: Norway | H14: =IF(ISNUMBER('GraphData'!B93),'GraphData'!B93,"n.d.") -> 11211.459 | K14: =IF(ISNUMBER('GraphData'!C93),'GraphData'!C93,"n.d.") -> 2025.348 | N14: =IF(ISNUMBER('GraphData'!D93),'GraphData'!D93,"n.d.") -> -0.81935018 | R14: Norway | W14: =IF(ISNUMBER('GraphData'!C93),'GraphData'!C93,"n.d.") -> 2025.348 | Z14: =IF(ISNUMBER('GraphData'!F93),'GraphData'!F93,"n.d.") -> 0 | AB14: =IF(ISNUMBER('GraphData'!G93),'GraphData'!G93,"n.d.") -> 0 | AD14: =IF(ISNUMBER('GraphData'!H93),'GraphData'!H93,"n.d.") -> 2025.348
B15: Sweden | H15: =IF(ISNUMBER('GraphData'!B94),'GraphData'!B94,"n.d.") -> 13809.271 | K15: =IF(ISNUMBER('GraphData'!C94),'GraphData'!C94,"n.d.") -> 15218.246 | N15: =IF(ISNUMBER('GraphData'!D94),'GraphData'!D94,"n.d.") -> 0.10203106 | R15: Sweden | W15: =IF(ISNUMBER('GraphData'!C94),'GraphData'!C94,"n.d.") -> 15218.246 | Z15: =IF(ISNUMBER('GraphData'!F94),'GraphData'!F94,"n.d.") -> 0 | AB15: =IF(ISNUMBER('GraphData'!G94),'GraphData'!G94,"n.d.") -> 0 | AD15: =IF(ISNUMBER('GraphData'!H94),'GraphData'!H94,"n.d.") -> 15218.246
B16: TOTAL available perimeter | H16: =IF(COUNT(H11:H15)=5,SUM(H11:H15),"n.d.") -> 3913006.3 | K16: =IF(COUNT(K11:K15)=5,SUM(K11:K15),"n.d.") -> 3794575.7 | N16: =IF(OR(COUNT(H16,K16)<>2,H16=0),"n.d.",K16/H16-1) -> -0.030265884 | R16: TOTAL available | W16: =IF(COUNT(W11:W15)=5,SUM(W11:W15),"n.d.") -> 3794575.7 | Z16: =IF(COUNT(Z11:Z15)=5,SUM(Z11:Z15),"n.d.") -> 3645132.6 | AB16: =IF(COUNT(AB11:AB15)=5,SUM(AB11:AB15),"n.d.") -> 112194 | AD16: =IF(COUNT(AD11:AD15)=5,SUM(AD11:AD15),"n.d.") -> 37249.084
R21: Waiting accounts for Nordics (CST)
R23: Country | W23: 2026Q2 EUR | AA23: 2026Q3 EUR | AE23: Change
B24: Romania closing stock is confirmed at zero. Nordic stock excludes separate CST account balances.
B26: Q2 and Q3 use Q3 closing FX. Stock breakdowns retain each country’s reporting scope. | R26: Denmark | W26: n.d. | AA26: n.d. | AE26: n.d.
R27: Norway | W27: n.d. | AA27: n.d. | AE27: n.d.
R28: Sweden | W28: n.d. | AA28: n.d. | AE28: n.d.
R31: Romania: Q3 closing stock confirmed at zero; monthly flow and treatment figures not provided. Separate Nordic CST account balances remain unavailable. CSR transfers are movements, not account balances.
B42: Positive Balance 2026Q3 Updated country inputs and closing FX Internal

Sheet ES Spain
B2: Spain | R2: STOCK OF POSITIVE BALANCES Breakdown by amount and vintage | X2: 46295
X3: Number of contracts | Z3: Total amount EUR | AC3: % in number | AE3: % in amount
B5: 2026Q3 — EUR. Stock breakdown and identified stock may have different scopes.
R7: By step of amount | U7: 0 - 1 € | X7: =IF((IF(OR(SUMPRODUCT(--('Repartition stock'!$A$6:$A$433="2026Q3"),--('Repartition stock'!$B$6:$B$433="ES"),--('Repartition stock'!$E$6:$E$433="Tranche"),--('Repartition stock'!$F$6:$F$433="0 - 1 €"))=0,SUMPRODUCT(--('Repartition stock'!$A$6:$A$433="2026Q3"),--('Repartition stock'!$B$6:$B$433="ES"),--('Repartition stock'!$E$6:$E$433="Tranche"),--('Repartition stock'!$F$6:$F$433="0 - 1 €"),--('Repartition stock'!$G$6:$G$433="n.d."))>0),"n.d.",SUMPRODUCT(--('Repartition stock'!$A$6:$A$433="2026Q3"),--('Repartition stock'!$B$6:$B$433="ES"),--('Repartition stock'!$E$6:$E$433="Tranche"),--('Repartition stock'!$F$6:$F$433="0 - 1 €"),'Repartition stock'!$G$6:$G$433)))="n.d.",0,IF(OR(SUMPRODUCT(--('Repartition stock'!$A$6:$A$433="2026Q3"),--('Repartition stock'!$B$6:$B$433="ES"),--('Repartition stock'!$E$6:$E$433="Tranche"),--('Repartition stock'!$F$6:$F$433="0 - 1 €"))=0,SUMPRODUCT(--('Repartition stock'!$A$6:$A$433="2026Q3"),--('Repartition stock'!$B$6:$B$433="ES"),--('Repartition stock'!$E$6:$E$433="Tranche"),--('Repartition stock'!$F$6:$F$433="0 - 1 €"),--('Repartition stock'!$G$6:$G$433="n.d."))>0),"n.d.",SUMPRODUCT(--('Repartition stock'!$A$6:$A$433="2026Q3"),--('Repartition stock'!$B$6:$B$433="ES"),--('Repartition stock'!$E$6:$E$433="Tranche"),--('Repartition stock'!$F$6:$F$433="0 - 1 €"),'Repartition stock'!$G$6:$G$433))) -> 183 | Z7: =IF((IF(OR(SUMPRODUCT(--('Repartition stock'!$A$6:$A$433="2026Q3"),--('Repartition stock'!$B$6:$B$433="ES"),--('Repartition stock'!$E$6:$E$433="Tranche"),--('Repartition stock'!$F$6:$F$433="0 - 1 €"))=0,SUMPRODUCT(--('Repartition stock'!$A$6:$A$433="2026Q3"),--('Repartition stock'!$B$6:$B$433="ES"),--('Repartition stock'!$E$6:$E$433="Tranche"),--('Repartition stock'!$F$6:$F$433="0 - 1 €"),--('Repartition stock'!$J$6:$J$433="n.d."))>0),"n.d.",SUMPRODUCT(--('Repartition stock'!$A$6:$A$433="2026Q3"),--('Repartition stock'!$B$6:$B$433="ES"),--('Repartition stock'!$E$6:$E$433="Tranche"),--('Repartition stock'!$F$6:$F$433="0 - 1 €"),'Repartition stock'!$J$6:$J$433)))="n.d.",0,IF(OR(SUMPRODUCT(--('Repartition stock'!$A$6:$A$433="2026Q3"),--('Repartition stock'!$B$6:$B$433="ES"),--('Repartition stock'!$E$6:$E$433="Tranche"),--('Repartition stock'!$F$6:$F$433="0 - 1 €"))=0,SUMPRODUCT(--('Repartition stock'!$A$6:$A$433="2026Q3"),--('Repartition stock'!$B$6:$B$433="ES"),--('Repartition stock'!$E$6:$E$433="Tranche"),--('Repartition stock'!$F$6:$F$433="0 - 1 €"),--('Repartition stock'!$J$6:$J$433="n.d."))>0),"n.d.",SUMPRODUCT(--('Repartition stock'!$A$6:$A$433="2026Q3"),--('Repartition stock'!$B$6:$B$433="ES"),--('Repartition stock'!$E$6:$E$433="Tranche"),--('Repartition stock'!$F$6:$F$433="0 - 1 €"),'Repartition stock'!$J$6:$J$433))) -> 27 | AC7: =IF((IF(OR(COUNT(X7,X12)<>2,X12=0),"n.d.",X7/X12))="n.d.",0,IF(OR(COUNT(X7,X12)<>2,X12=0),"n.d.",X7/X12)) -> 0.023214512 | AE7: =IF((IF(OR(COUNT(Z7,Z12)<>2,Z12=0),"n.d.",Z7/Z12))="n.d.",0,IF(OR(COUNT(Z7,Z12)<>2,Z12=0),"n.d.",Z7/Z12)) -> 1.820176e-05
U8: 1 - 10 € | X8: =IF((IF(OR(SUMPRODUCT(--('Repartition stock'!$A$6:$A$433="2026Q3"),--('Repartition stock'!$B$6:$B$433="ES"),--('Repartition stock'!$E$6:$E$433="Tranche"),--('Repartition stock'!$F$6:$F$433="1 - 10 €"))=0,SUMPRODUCT(--('Repartition stock'!$A$6:$A$433="2026Q3"),--('Repartition stock'!$B$6:$B$433="ES"),--('Repartition stock'!$E$6:$E$433="Tranche"),--('Repartition stock'!$F$6:$F$433="1 - 10 €"),--('Repartition stock'!$G$6:$G$433="n.d."))>0),"n.d.",SUMPRODUCT(--('Repartition stock'!$A$6:$A$433="2026Q3"),--('Repartition stock'!$B$6:$B$433="ES"),--('Repartition stock'!$E$6:$E$433="Tranche"),--('Repartition stock'!$F$6:$F$433="1 - 10 €"),'Repartition stock'!$G$6:$G$433)))="n.d.",0,IF(OR(SUMPRODUCT(--('Repartition stock'!$A$6:$A$433="2026Q3"),--('Repartition stock'!$B$6:$B$433="ES"),--('Repartition stock'!$E$6:$E$433="Tranche"),--('Repartition stock'!$F$6:$F$433="1 - 10 €"))=0,SUMPRODUCT(--('Repartition stock'!$A$6:$A$433="2026Q3"),--('Repartition stock'!$B$6:$B$433="ES"),--('Repartition stock'!$E$6:$E$433="Tranche"),--('Repartition stock'!$F$6:$F$433="1 - 10 €"),--('Repartition stock'!$G$6:$G$433="n.d."))>0),"n.d.",SUMPRODUCT(--('Repartition stock'!$A$6:$A$433="2026Q3"),--('Repartition stock'!$B$6:$B$433="ES"),--('Repartition stock'!$E$6:$E$433="Tranche"),--('Repartition stock'!$F$6:$F$433="1 - 10 €"),'Repartition stock'!$G$6:$G$433))) -> 469 | Z8: =IF((IF(OR(SUMPRODUCT(--('Repartition stock'!$A$6:$A$433="2026Q3"),--('Repartition stock'!$B$6:$B$433="ES"),--('Repartition stock'!$E$6:$E$433="Tranche"),--('Repartition stock'!$F$6:$F$433="1 - 10 €"))=0,SUMPRODUCT(--('Repartition stock'!$A$6:$A$433="2026Q3"),--('Repartition stock'!$B$6:$B$433="ES"),--('Repartition stock'!$E$6:$E$433="Tranche"),--('Repartition stock'!$F$6:$F$433="1 - 10 €"),--('Repartition stock'!$J$6:$J$433="n.d."))>0),"n.d.",SUMPRODUCT(--('Repartition stock'!$A$6:$A$433="2026Q3"),--('Repartition stock'!$B$6:$B$433="ES"),--('Repartition stock'!$E$6:$E$433="Tranche"),--('Repartition stock'!$F$6:$F$433="1 - 10 €"),'Repartition stock'!$J$6:$J$433)))="n.d.",0,IF(OR(SUMPRODUCT(--('Repartition stock'!$A$6:$A$433="2026Q3"),--('Repartition stock'!$B$6:$B$433="ES"),--('Repartition stock'!$E$6:$E$433="Tranche"),--('Repartition stock'!$F$6:$F$433="1 - 10 €"))=0,SUMPRODUCT(--('Repartition stock'!$A$6:$A$433="2026Q3"),--('Repartition stock'!$B$6:$B$433="ES"),--('Repartition stock'!$E$6:$E$433="Tranche"),--('Repartition stock'!$F$6:$F$433="1 - 10 €"),--('Repartition stock'!$J$6:$J$433="n.d."))>0),"n.d.",SUMPRODUCT(--('Repartition stock'!$A$6:$A$433="2026Q3"),--('Repartition stock'!$B$6:$B$433="ES"),--('Repartition stock'!$E$6:$E$433="Tranche"),--('Repartition stock'!$F$6:$F$433="1 - 10 €"),'Repartition stock'!$J$6:$J$433))) -> 2417 | AC8: =IF((IF(OR(COUNT(X8,X12)<>2,X12=0),"n.d.",X8/X12))="n.d.",0,IF(OR(COUNT(X8,X12)<>2,X12=0),"n.d.",X8/X12)) -> 0.059495116 | AE8: =IF((IF(OR(COUNT(Z8,Z12)<>2,Z12=0),"n.d.",Z8/Z12))="n.d.",0,IF(OR(COUNT(Z8,Z12)<>2,Z12=0),"n.d.",Z8/Z12)) -> 0.0016293946
U9: 10 - 100 € | X9: =IF((IF(OR(SUMPRODUCT(--('Repartition stock'!$A$6:$A$433="2026Q3"),--('Repartition stock'!$B$6:$B$433="ES"),--('Repartition stock'!$E$6:$E$433="Tranche"),--('Repartition stock'!$F$6:$F$433="10 - 100 €"))=0,SUMPRODUCT(--('Repartition stock'!$A$6:$A$433="2026Q3"),--('Repartition stock'!$B$6:$B$433="ES"),--('Repartition stock'!$E$6:$E$433="Tranche"),--('Repartition stock'!$F$6:$F$433="10 - 100 €"),--('Repartition stock'!$G$6:$G$433="n.d."))>0),"n.d.",SUMPRODUCT(--('Repartition stock'!$A$6:$A$433="2026Q3"),--('Repartition stock'!$B$6:$B$433="ES"),--('Repartition stock'!$E$6:$E$433="Tranche"),--('Repartition stock'!$F$6:$F$433="10 - 100 €"),'Repartition stock'!$G$6:$G$433)))="n.d.",0,IF(OR(SUMPRODUCT(--('Repartition stock'!$A$6:$A$433="2026Q3"),--('Repartition stock'!$B$6:$B$433="ES"),--('Repartition stock'!$E$6:$E$433="Tranche"),--('Repartition stock'!$F$6:$F$433="10 - 100 €"))=0,SUMPRODUCT(--('Repartition stock'!$A$6:$A$433="2026Q3"),--('Repartition stock'!$B$6:$B$433="ES"),--('Repartition stock'!$E$6:$E$433="Tranche"),--('Repartition stock'!$F$6:$F$433="10 - 100 €"),--('Repartition stock'!$G$6:$G$433="n.d."))>0),"n.d.",SUMPRODUCT(--('Repartition stock'!$A$6:$A$433="2026Q3"),--('Repartition stock'!$B$6:$B$433="ES"),--('Repartition stock'!$E$6:$E$433="Tranche"),--('Repartition stock'!$F$6:$F$433="10 - 100 €"),'Repartition stock'!$G$6:$G$433))) -> 4270 | Z9: =IF((IF(OR(SUMPRODUCT(--('Repartition stock'!$A$6:$A$433="2026Q3"),--('Repartition stock'!$B$6:$B$433="ES"),--('Repartition stock'!$E$6:$E$433="Tranche"),--('Repartition stock'!$F$6:$F$433="10 - 100 €"))=0,SUMPRODUCT(--('Repartition stock'!$A$6:$A$433="2026Q3"),--('Repartition stock'!$B$6:$B$433="ES"),--('Repartition stock'!$E$6:$E$433="Tranche"),--('Repartition stock'!$F$6:$F$433="10 - 100 €"),--('Repartition stock'!$J$6:$J$433="n.d."))>0),"n.d.",SUMPRODUCT(--('Repartition stock'!$A$6:$A$433="2026Q3"),--('Repartition stock'!$B$6:$B$433="ES"),--('Repartition stock'!$E$6:$E$433="Tranche"),--('Repartition stock'!$F$6:$F$433="10 - 100 €"),'Repartition stock'!$J$6:$J$433)))="n.d.",0,IF(OR(SUMPRODUCT(--('Repartition stock'!$A$6:$A$433="2026Q3"),--('Repartition stock'!$B$6:$B$433="ES"),--('Repartition stock'!$E$6:$E$433="Tranche"),--('Repartition stock'!$F$6:$F$433="10 - 100 €"))=0,SUMPRODUCT(--('Repartition stock'!$A$6:$A$433="2026Q3"),--('Repartition stock'!$B$6:$B$433="ES"),--('Repartition stock'!$E$6:$E$433="Tranche"),--('Repartition stock'!$F$6:$F$433="10 - 100 €"),--('Repartition stock'!$J$6:$J$433="n.d."))>0),"n.d.",SUMPRODUCT(--('Repartition stock'!$A$6:$A$433="2026Q3"),--('Repartition stock'!$B$6:$B$433="ES"),--('Repartition stock'!$E$6:$E$433="Tranche"),--('Repartition stock'!$F$6:$F$433="10 - 100 €"),'Repartition stock'!$J$6:$J$433))) -> 203009 | AC9: =IF((IF(OR(COUNT(X9,X12)<>2,X12=0),"n.d.",X9/X12))="n.d.",0,IF(OR(COUNT(X9,X12)<>2,X12=0),"n.d.",X9/X12)) -> 0.54167195 | AE9: =IF((IF(OR(COUNT(Z9,Z12)<>2,Z12=0),"n.d.",Z9/Z12))="n.d.",0,IF(OR(COUNT(Z9,Z12)<>2,Z12=0),"n.d.",Z9/Z12)) -> 0.13685634
U10: 100 - 1 000 € | X10: =IF((IF(OR(SUMPRODUCT(--('Repartition stock'!$A$6:$A$433="2026Q3"),--('Repartition stock'!$B$6:$B$433="ES"),--('Repartition stock'!$E$6:$E$433="Tranche"),--('Repartition stock'!$F$6:$F$433="100 - 1 000 €"))=0,SUMPRODUCT(--('Repartition stock'!$A$6:$A$433="2026Q3"),--('Repartition stock'!$B$6:$B$433="ES"),--('Repartition stock'!$E$6:$E$433="Tranche"),--('Repartition stock'!$F$6:$F$433="100 - 1 000 €"),--('Repartition stock'!$G$6:$G$433="n.d."))>0),"n.d.",SUMPRODUCT(--('Repartition stock'!$A$6:$A$433="2026Q3"),--('Repartition stock'!$B$6:$B$433="ES"),--('Repartition stock'!$E$6:$E$433="Tranche"),--('Repartition stock'!$F$6:$F$433="100 - 1 000 €"),'Repartition stock'!$G$6:$G$433)))="n.d.",0,IF(OR(SUMPRODUCT(--('Repartition stock'!$A$6:$A$433="2026Q3"),--('Repartition stock'!$B$6:$B$433="ES"),--('Repartition stock'!$E$6:$E$433="Tranche"),--('Repartition stock'!$F$6:$F$433="100 - 1 000 €"))=0,SUMPRODUCT(--('Repartition stock'!$A$6:$A$433="2026Q3"),--('Repartition stock'!$B$6:$B$433="ES"),--('Repartition stock'!$E$6:$E$433="Tranche"),--('Repartition stock'!$F$6:$F$433="100 - 1 000 €"),--('Repartition stock'!$G$6:$G$433="n.d."))>0),"n.d.",SUMPRODUCT(--('Repartition stock'!$A$6:$A$433="2026Q3"),--('Repartition stock'!$B$6:$B$433="ES"),--('Repartition stock'!$E$6:$E$433="Tranche"),--('Repartition stock'!$F$6:$F$433="100 - 1 000 €"),'Repartition stock'!$G$6:$G$433))) -> 2772 | Z10: =IF((IF(OR(SUMPRODUCT(--('Repartition stock'!$A$6:$A$433="2026Q3"),--('Repartition stock'!$B$6:$B$433="ES"),--('Repartition stock'!$E$6:$E$433="Tranche"),--('Repartition stock'!$F$6:$F$433="100 - 1 000 €"))=0,SUMPRODUCT(--('Repartition stock'!$A$6:$A$433="2026Q3"),--('Repartition stock'!$B$6:$B$433="ES"),--('Repartition stock'!$E$6:$E$433="Tranche"),--('Repartition stock'!$F$6:$F$433="100 - 1 000 €"),--('Repartition stock'!$J$6:$J$433="n.d."))>0),"n.d.",SUMPRODUCT(--('Repartition stock'!$A$6:$A$433="2026Q3"),--('Repartition stock'!$B$6:$B$433="ES"),--('Repartition stock'!$E$6:$E$433="Tranche"),--('Repartition stock'!$F$6:$F$433="100 - 1 000 €"),'Repartition stock'!$J$6:$J$433)))="n.d.",0,IF(OR(SUMPRODUCT(--('Repartition stock'!$A$6:$A$433="2026Q3"),--('Repartition stock'!$B$6:$B$433="ES"),--('Repartition stock'!$E$6:$E$433="Tranche"),--('Repartition stock'!$F$6:$F$433="100 - 1 000 €"))=0,SUMPRODUCT(--('Repartition stock'!$A$6:$A$433="2026Q3"),--('Repartition stock'!$B$6:$B$433="ES"),--('Repartition stock'!$E$6:$E$433="Tranche"),--('Repartition stock'!$F$6:$F$433="100 - 1 000 €"),--('Repartition stock'!$J$6:$J$433="n.d."))>0),"n.d.",SUMPRODUCT(--('Repartition stock'!$A$6:$A$433="2026Q3"),--('Repartition stock'!$B$6:$B$433="ES"),--('Repartition stock'!$E$6:$E$433="Tranche"),--('Repartition stock'!$F$6:$F$433="100 - 1 000 €"),'Repartition stock'!$J$6:$J$433))) -> 686886 | AC10: =IF((IF(OR(COUNT(X10,X12)<>2,X12=0),"n.d.",X10/X12))="n.d.",0,IF(OR(COUNT(X10,X12)<>2,X12=0),"n.d.",X10/X12)) -> 0.35164278 | AE10: =IF((IF(OR(COUNT(Z10,Z12)<>2,Z12=0),"n.d.",Z10/Z12))="n.d.",0,IF(OR(COUNT(Z10,Z12)<>2,Z12=0),"n.d.",Z10/Z12)) -> 0.46305683
U11: > 1 000 € | X11: =IF((IF(OR(SUMPRODUCT(--('Repartition stock'!$A$6:$A$433="2026Q3"),--('Repartition stock'!$B$6:$B$433="ES"),--('Repartition stock'!$E$6:$E$433="Tranche"),--('Repartition stock'!$F$6:$F$433="> 1 000 €"))=0,SUMPRODUCT(--('Repartition stock'!$A$6:$A$433="2026Q3"),--('Repartition stock'!$B$6:$B$433="ES"),--('Repartition stock'!$E$6:$E$433="Tranche"),--('Repartition stock'!$F$6:$F$433="> 1 000 €"),--('Repartition stock'!$G$6:$G$433="n.d."))>0),"n.d.",SUMPRODUCT(--('Repartition stock'!$A$6:$A$433="2026Q3"),--('Repartition stock'!$B$6:$B$433="ES"),--('Repartition stock'!$E$6:$E$433="Tranche"),--('Repartition stock'!$F$6:$F$433="> 1 000 €"),'Repartition stock'!$G$6:$G$433)))="n.d.",0,IF(OR(SUMPRODUCT(--('Repartition stock'!$A$6:$A$433="2026Q3"),--('Repartition stock'!$B$6:$B$433="ES"),--('Repartition stock'!$E$6:$E$433="Tranche"),--('Repartition stock'!$F$6:$F$433="> 1 000 €"))=0,SUMPRODUCT(--('Repartition stock'!$A$6:$A$433="2026Q3"),--('Repartition stock'!$B$6:$B$433="ES"),--('Repartition stock'!$E$6:$E$433="Tranche"),--('Repartition stock'!$F$6:$F$433="> 1 000 €"),--('Repartition stock'!$G$6:$G$433="n.d."))>0),"n.d.",SUMPRODUCT(--('Repartition stock'!$A$6:$A$433="2026Q3"),--('Repartition stock'!$B$6:$B$433="ES"),--('Repartition stock'!$E$6:$E$433="Tranche"),--('Repartition stock'!$F$6:$F$433="> 1 000 €"),'Repartition stock'!$G$6:$G$433))) -> 189 | Z11: =IF((IF(OR(SUMPRODUCT(--('Repartition stock'!$A$6:$A$433="2026Q3"),--('Repartition stock'!$B$6:$B$433="ES"),--('Repartition stock'!$E$6:$E$433="Tranche"),--('Repartition stock'!$F$6:$F$433="> 1 000 €"))=0,SUMPRODUCT(--('Repartition stock'!$A$6:$A$433="2026Q3"),--('Repartition stock'!$B$6:$B$433="ES"),--('Repartition stock'!$E$6:$E$433="Tranche"),--('Repartition stock'!$F$6:$F$433="> 1 000 €"),--('Repartition stock'!$J$6:$J$433="n.d."))>0),"n.d.",SUMPRODUCT(--('Repartition stock'!$A$6:$A$433="2026Q3"),--('Repartition stock'!$B$6:$B$433="ES"),--('Repartition stock'!$E$6:$E$433="Tranche"),--('Repartition stock'!$F$6:$F$433="> 1 000 €"),'Repartition stock'!$J$6:$J$433)))="n.d.",0,IF(OR(SUMPRODUCT(--('Repartition stock'!$A$6:$A$433="2026Q3"),--('Repartition stock'!$B$6:$B$433="ES"),--('Repartition stock'!$E$6:$E$433="Tranche"),--('Repartition stock'!$F$6:$F$433="> 1 000 €"))=0,SUMPRODUCT(--('Repartition stock'!$A$6:$A$433="2026Q3"),--('Repartition stock'!$B$6:$B$433="ES"),--('Repartition stock'!$E$6:$E$433="Tranche"),--('Repartition stock'!$F$6:$F$433="> 1 000 €"),--('Repartition stock'!$J$6:$J$433="n.d."))>0),"n.d.",SUMPRODUCT(--('Repartition stock'!$A$6:$A$433="2026Q3"),--('Repartition stock'!$B$6:$B$433="ES"),--('Repartition stock'!$E$6:$E$433="Tranche"),--('Repartition stock'!$F$6:$F$433="> 1 000 €"),'Repartition stock'!$J$6:$J$433))) -> 591034 | AC11: =IF((IF(OR(COUNT(X11,X12)<>2,X12=0),"n.d.",X11/X12))="n.d.",0,IF(OR(COUNT(X11,X12)<>2,X12=0),"n.d.",X11/X12)) -> 0.023975644 | AE11: =IF((IF(OR(COUNT(Z11,Z12)<>2,Z12=0),"n.d.",Z11/Z12))="n.d.",0,IF(OR(COUNT(Z11,Z12)<>2,Z12=0),"n.d.",Z11/Z12)) -> 0.39843923
R12: Total: | X12: =IF((IF(COUNT(X7:X11)=5,SUM(X7:X11),"n.d."))="n.d.",0,IF(COUNT(X7:X11)=5,SUM(X7:X11),"n.d.")) -> 7883 | Z12: =IF((IF(COUNT(Z7:Z11)=5,SUM(Z7:Z11),"n.d."))="n.d.",0,IF(COUNT(Z7:Z11)=5,SUM(Z7:Z11),"n.d.")) -> 1483373 | AC12: =IF((IF(OR(NOT(ISNUMBER(X12)),X12=0),"n.d.",1))="n.d.",0,IF(OR(NOT(ISNUMBER(X12)),X12=0),"n.d.",1)) -> 1 | AE12: =IF((IF(OR(NOT(ISNUMBER(Z12)),Z12=0),"n.d.",1))="n.d.",0,IF(OR(NOT(ISNUMBER(Z12)),Z12=0),"n.d.",1)) -> 1
R14: By date of positive balance | U14: <2018 | X14: =IF((IF(OR(SUMPRODUCT(--('Repartition stock'!$A$6:$A$433="2026Q3"),--('Repartition stock'!$B$6:$B$433="ES"),--('Repartition stock'!$E$6:$E$433="Millésime"),--('Repartition stock'!$F$6:$F$433="<2018"))=0,SUMPRODUCT(--('Repartition stock'!$A$6:$A$433="2026Q3"),--('Repartition stock'!$B$6:$B$433="ES"),--('Repartition stock'!$E$6:$E$433="Millésime"),--('Repartition stock'!$F$6:$F$433="<2018"),--('Repartition stock'!$G$6:$G$433="n.d."))>0),"n.d.",SUMPRODUCT(--('Repartition stock'!$A$6:$A$433="2026Q3"),--('Repartition stock'!$B$6:$B$433="ES"),--('Repartition stock'!$E$6:$E$433="Millésime"),--('Repartition stock'!$F$6:$F$433="<2018"),'Repartition stock'!$G$6:$G$433)))="n.d.",0,IF(OR(SUMPRODUCT(--('Repartition stock'!$A$6:$A$433="2026Q3"),--('Repartition stock'!$B$6:$B$433="ES"),--('Repartition stock'!$E$6:$E$433="Millésime"),--('Repartition stock'!$F$6:$F$433="<2018"))=0,SUMPRODUCT(--('Repartition stock'!$A$6:$A$433="2026Q3"),--('Repartition stock'!$B$6:$B$433="ES"),--('Repartition stock'!$E$6:$E$433="Millésime"),--('Repartition stock'!$F$6:$F$433="<2018"),--('Repartition stock'!$G$6:$G$433="n.d."))>0),"n.d.",SUMPRODUCT(--('Repartition stock'!$A$6:$A$433="2026Q3"),--('Repartition stock'!$B$6:$B$433="ES"),--('Repartition stock'!$E$6:$E$433="Millésime"),--('Repartition stock'!$F$6:$F$433="<2018"),'Repartition stock'!$G$6:$G$433))) -> 0 | Z14: =IF((IF(OR(SUMPRODUCT(--('Repartition stock'!$A$6:$A$433="2026Q3"),--('Repartition stock'!$B$6:$B$433="ES"),--('Repartition stock'!$E$6:$E$433="Millésime"),--('Repartition stock'!$F$6:$F$433="<2018"))=0,SUMPRODUCT(--('Repartition stock'!$A$6:$A$433="2026Q3"),--('Repartition stock'!$B$6:$B$433="ES"),--('Repartition stock'!$E$6:$E$433="Millésime"),--('Repartition stock'!$F$6:$F$433="<2018"),--('Repartition stock'!$J$6:$J$433="n.d."))>0),"n.d.",SUMPRODUCT(--('Repartition stock'!$A$6:$A$433="2026Q3"),--('Repartition stock'!$B$6:$B$433="ES"),--('Repartition stock'!$E$6:$E$433="Millésime"),--('Repartition stock'!$F$6:$F$433="<2018"),'Repartition stock'!$J$6:$J$433)))="n.d.",0,IF(OR(SUMPRODUCT(--('Repartition stock'!$A$6:$A$433="2026Q3"),--('Repartition stock'!$B$6:$B$433="ES"),--('Repartition stock'!$E$6:$E$433="Millésime"),--('Repartition stock'!$F$6:$F$433="<2018"))=0,SUMPRODUCT(--('Repartition stock'!$A$6:$A$433="2026Q3"),--('Repartition stock'!$B$6:$B$433="ES"),--('Repartition stock'!$E$6:$E$433="Millésime"),--('Repartition stock'!$F$6:$F$433="<2018"),--('Repartition stock'!$J$6:$J$433="n.d."))>0),"n.d.",SUMPRODUCT(--('Repartition stock'!$A$6:$A$433="2026Q3"),--('Repartition stock'!$B$6:$B$433="ES"),--('Repartition stock'!$E$6:$E$433="Millésime"),--('Repartition stock'!$F$6:$F$433="<2018"),'Repartition stock'!$J$6:$J$433))) -> 0 | AC14: =IF((IF(OR(COUNT(X14,X24)<>2,X24=0),"n.d.",X14/X24))="n.d.",0,IF(OR(COUNT(X14,X24)<>2,X24=0),"n.d.",X14/X24)) -> 0 | AE14: =IF((IF(OR(COUNT(Z14,Z24)<>2,Z24=0),"n.d.",Z14/Z24))="n.d.",0,IF(OR(COUNT(Z14,Z24)<>2,Z24=0),"n.d.",Z14/Z24)) -> 0
U15: 2018 | X15: =IF((IF(OR(SUMPRODUCT(--('Repartition stock'!$A$6:$A$433="2026Q3"),--('Repartition stock'!$B$6:$B$433="ES"),--('Repartition stock'!$E$6:$E$433="Millésime"),--('Repartition stock'!$F$6:$F$433="2018"))=0,SUMPRODUCT(--('Repartition stock'!$A$6:$A$433="2026Q3"),--('Repartition stock'!$B$6:$B$433="ES"),--('Repartition stock'!$E$6:$E$433="Millésime"),--('Repartition stock'!$F$6:$F$433="2018"),--('Repartition stock'!$G$6:$G$433="n.d."))>0),"n.d.",SUMPRODUCT(--('Repartition stock'!$A$6:$A$433="2026Q3"),--('Repartition stock'!$B$6:$B$433="ES"),--('Repartition stock'!$E$6:$E$433="Millésime"),--('Repartition stock'!$F$6:$F$433="2018"),'Repartition stock'!$G$6:$G$433)))="n.d.",0,IF(OR(SUMPRODUCT(--('Repartition stock'!$A$6:$A$433="2026Q3"),--('Repartition stock'!$B$6:$B$433="ES"),--('Repartition stock'!$E$6:$E$433="Millésime"),--('Repartition stock'!$F$6:$F$433="2018"))=0,SUMPRODUCT(--('Repartition stock'!$A$6:$A$433="2026Q3"),--('Repartition stock'!$B$6:$B$433="ES"),--('Repartition stock'!$E$6:$E$433="Millésime"),--('Repartition stock'!$F$6:$F$433="2018"),--('Repartition stock'!$G$6:$G$433="n.d."))>0),"n.d.",SUMPRODUCT(--('Repartition stock'!$A$6:$A$433="2026Q3"),--('Repartition stock'!$B$6:$B$433="ES"),--('Repartition stock'!$E$6:$E$433="Millésime"),--('Repartition stock'!$F$6:$F$433="2018"),'Repartition stock'!$G$6:$G$433))) -> 0 | Z15: =IF((IF(OR(SUMPRODUCT(--('Repartition stock'!$A$6:$A$433="2026Q3"),--('Repartition stock'!$B$6:$B$433="ES"),--('Repartition stock'!$E$6:$E$433="Millésime"),--('Repartition stock'!$F$6:$F$433="2018"))=0,SUMPRODUCT(--('Repartition stock'!$A$6:$A$433="2026Q3"),--('Repartition stock'!$B$6:$B$433="ES"),--('Repartition stock'!$E$6:$E$433="Millésime"),--('Repartition stock'!$F$6:$F$433="2018"),--('Repartition stock'!$J$6:$J$433="n.d."))>0),"n.d.",SUMPRODUCT(--('Repartition stock'!$A$6:$A$433="2026Q3"),--('Repartition stock'!$B$6:$B$433="ES"),--('Repartition stock'!$E$6:$E$433="Millésime"),--('Repartition stock'!$F$6:$F$433="2018"),'Repartition stock'!$J$6:$J$433)))="n.d.",0,IF(OR(SUMPRODUCT(--('Repartition stock'!$A$6:$A$433="2026Q3"),--('Repartition stock'!$B$6:$B$433="ES"),--('Repartition stock'!$E$6:$E$433="Millésime"),--('Repartition stock'!$F$6:$F$433="2018"))=0,SUMPRODUCT(--('Repartition stock'!$A$6:$A$433="2026Q3"),--('Repartition stock'!$B$6:$B$433="ES"),--('Repartition stock'!$E$6:$E$433="Millésime"),--('Repartition stock'!$F$6:$F$433="2018"),--('Repartition stock'!$J$6:$J$433="n.d."))>0),"n.d.",SUMPRODUCT(--('Repartition stock'!$A$6:$A$433="2026Q3"),--('Repartition stock'!$B$6:$B$433="ES"),--('Repartition stock'!$E$6:$E$433="Millésime"),--('Repartition stock'!$F$6:$F$433="2018"),'Repartition stock'!$J$6:$J$433))) -> 0 | AC15: =IF((IF(OR(COUNT(X15,X24)<>2,X24=0),"n.d.",X15/X24))="n.d.",0,IF(OR(COUNT(X15,X24)<>2,X24=0),"n.d.",X15/X24)) -> 0 | AE15: =IF((IF(OR(COUNT(Z15,Z24)<>2,Z24=0),"n.d.",Z15/Z24))="n.d.",0,IF(OR(COUNT(Z15,Z24)<>2,Z24=0),"n.d.",Z15/Z24)) -> 0
